no change     /home1/04637/mdl2665/anaconda3/condabin/conda
no change     /home1/04637/mdl2665/anaconda3/bin/conda
no change     /home1/04637/mdl2665/anaconda3/bin/conda-env
no change     /home1/04637/mdl2665/anaconda3/bin/activate
no change     /home1/04637/mdl2665/anaconda3/bin/deactivate
no change     /home1/04637/mdl2665/anaconda3/etc/profile.d/conda.sh
no change     /home1/04637/mdl2665/anaconda3/etc/fish/conf.d/conda.fish
no change     /home1/04637/mdl2665/anaconda3/shell/condabin/Conda.psm1
no change     /home1/04637/mdl2665/anaconda3/shell/condabin/conda-hook.ps1
no change     /home1/04637/mdl2665/anaconda3/lib/python3.9/site-packages/xontrib/conda.xsh
no change     /home1/04637/mdl2665/anaconda3/etc/profile.d/conda.csh
no change     /home1/04637/mdl2665/.bashrc
No action taken.

     active environment : fenicsx-env
    active env location : /home1/04637/mdl2665/anaconda3/envs/fenicsx-env
            shell level : 2
       user config file : /home1/04637/mdl2665/.condarc
 populated config files : 
          conda version : 4.12.0
    conda-build version : 3.21.8
         python version : 3.9.12.final.0
       virtual packages : __linux=4.18.0=0
                          __glibc=2.28=0
                          __unix=0=0
                          __archspec=1=x86_64
       base environment : /home1/04637/mdl2665/anaconda3  (writable)
      conda av data dir : /home1/04637/mdl2665/anaconda3/etc/conda
  conda av metadata url : None
           channel URLs : https://repo.anaconda.com/pkgs/main/linux-64
                          https://repo.anaconda.com/pkgs/main/noarch
                          https://repo.anaconda.com/pkgs/r/linux-64
                          https://repo.anaconda.com/pkgs/r/noarch
          package cache : /home1/04637/mdl2665/anaconda3/pkgs
                          /home1/04637/mdl2665/.conda/pkgs
       envs directories : /home1/04637/mdl2665/anaconda3/envs
                          /home1/04637/mdl2665/.conda/envs
               platform : linux-64
             user-agent : conda/4.12.0 requests/2.27.1 CPython/3.9.12 Linux/4.18.0-372.26.1.el8_6.x86_64 rocky/8.6 glibc/2.28
                UID:GID : 839365:819760
             netrc file : None
           offline mode : False

TACC:  Starting up job 629351 
TACC:  Starting parallel tasks... 
Switching to logarithmic spacing in frequency
Traceback (most recent call last):
  File "/home1/04637/mdl2665/WAVEx/main.py", line 259, in <module>
    c,dry_dofs_local,cph,k = CFx.wave.compute_wave_speeds(x,y,sigma,theta,depth_func,u_func,v_func,N_dof_2)
  File "/home1/04637/mdl2665/WAVEx/CFx/wave.py", line 213, in compute_wave_speeds
Traceback (most recent call last):
  File "/home1/04637/mdl2665/WAVEx/main.py", line 259, in <module>
    c,dry_dofs_local,cph,k = CFx.wave.compute_wave_speeds(x,y,sigma,theta,depth_func,u_func,v_func,N_dof_2)
  File "/home1/04637/mdl2665/WAVEx/CFx/wave.py", line 213, in compute_wave_speeds
Traceback (most recent call last):
  File "/home1/04637/mdl2665/WAVEx/main.py", line 259, in <module>
Traceback (most recent call last):
  File "/home1/04637/mdl2665/WAVEx/main.py", line 259, in <module>
    c,dry_dofs_local,cph,k = CFx.wave.compute_wave_speeds(x,y,sigma,theta,depth_func,u_func,v_func,N_dof_2)
  File "/home1/04637/mdl2665/WAVEx/CFx/wave.py", line 213, in compute_wave_speeds
    c_out[wet_dofs_local,:],cph[wet_dofs_local],k[wet_dofs_local] = compute_wave_speeds_pointwise(x[wet_dofs_local],y[wet_dofs_local],sigma[wet_dofs_local],theta[wet_dofs_local],depth[wet_dofs_local],
IndexError: index 24600 is out of bounds for axis 0 with size 24600
Traceback (most recent call last):
  File "/home1/04637/mdl2665/WAVEx/main.py", line 259, in <module>
Traceback (most recent call last):
  File "/home1/04637/mdl2665/WAVEx/main.py", line 259, in <module>
    c,dry_dofs_local,cph,k = CFx.wave.compute_wave_speeds(x,y,sigma,theta,depth_func,u_func,v_func,N_dof_2)
  File "/home1/04637/mdl2665/WAVEx/CFx/wave.py", line 213, in compute_wave_speeds
    c_out[wet_dofs_local,:],cph[wet_dofs_local],k[wet_dofs_local] = compute_wave_speeds_pointwise(x[wet_dofs_local],y[wet_dofs_local],sigma[wet_dofs_local],theta[wet_dofs_local],depth[wet_dofs_local],
IndexError: index 27675 is out of bounds for axis 0 with size 26650
Traceback (most recent call last):
  File "/home1/04637/mdl2665/WAVEx/main.py", line 259, in <module>
    c,dry_dofs_local,cph,k = CFx.wave.compute_wave_speeds(x,y,sigma,theta,depth_func,u_func,v_func,N_dof_2)
  File "/home1/04637/mdl2665/WAVEx/CFx/wave.py", line 213, in compute_wave_speeds
    c_out[wet_dofs_local,:],cph[wet_dofs_local],k[wet_dofs_local] = compute_wave_speeds_pointwise(x[wet_dofs_local],y[wet_dofs_local],sigma[wet_dofs_local],theta[wet_dofs_local],depth[wet_dofs_local],
IndexError: index 22550 is out of bounds for axis 0 with size 21525
Traceback (most recent call last):
  File "/home1/04637/mdl2665/WAVEx/main.py", line 259, in <module>
    c,dry_dofs_local,cph,k = CFx.wave.compute_wave_speeds(x,y,sigma,theta,depth_func,u_func,v_func,N_dof_2)
  File "/home1/04637/mdl2665/WAVEx/CFx/wave.py", line 213, in compute_wave_speeds
    c_out[wet_dofs_local,:],cph[wet_dofs_local],k[wet_dofs_local] = compute_wave_speeds_pointwise(x[wet_dofs_local],y[wet_dofs_local],sigma[wet_dofs_local],theta[wet_dofs_local],depth[wet_dofs_local],
IndexError: index 26650 is out of bounds for axis 0 with size 26650
Traceback (most recent call last):
  File "/home1/04637/mdl2665/WAVEx/main.py", line 259, in <module>
    c,dry_dofs_local,cph,k = CFx.wave.compute_wave_speeds(x,y,sigma,theta,depth_func,u_func,v_func,N_dof_2)
  File "/home1/04637/mdl2665/WAVEx/CFx/wave.py", line 213, in compute_wave_speeds
    c_out[wet_dofs_local,:],cph[wet_dofs_local],k[wet_dofs_local] = compute_wave_speeds_pointwise(x[wet_dofs_local],y[wet_dofs_local],sigma[wet_dofs_local],theta[wet_dofs_local],depth[wet_dofs_local],
IndexError: index 26650 is out of bounds for axis 0 with size 26650
Traceback (most recent call last):
  File "/home1/04637/mdl2665/WAVEx/main.py", line 259, in <module>
    c,dry_dofs_local,cph,k = CFx.wave.compute_wave_speeds(x,y,sigma,theta,depth_func,u_func,v_func,N_dof_2)
  File "/home1/04637/mdl2665/WAVEx/CFx/wave.py", line 213, in compute_wave_speeds
    c_out[wet_dofs_local,:],cph[wet_dofs_local],k[wet_dofs_local] = compute_wave_speeds_pointwise(x[wet_dofs_local],y[wet_dofs_local],sigma[wet_dofs_local],theta[wet_dofs_local],depth[wet_dofs_local],
IndexError: index 24600 is out of bounds for axis 0 with size 24600
Traceback (most recent call last):
  File "/home1/04637/mdl2665/WAVEx/main.py", line 259, in <module>
    c,dry_dofs_local,cph,k = CFx.wave.compute_wave_speeds(x,y,sigma,theta,depth_func,u_func,v_func,N_dof_2)
  File "/home1/04637/mdl2665/WAVEx/CFx/wave.py", line 213, in compute_wave_speeds
    c_out[wet_dofs_local,:],cph[wet_dofs_local],k[wet_dofs_local] = compute_wave_speeds_pointwise(x[wet_dofs_local],y[wet_dofs_local],sigma[wet_dofs_local],theta[wet_dofs_local],depth[wet_dofs_local],
IndexError: index 26650 is out of bounds for axis 0 with size 26650
Traceback (most recent call last):
  File "/home1/04637/mdl2665/WAVEx/main.py", line 259, in <module>
    c,dry_dofs_local,cph,k = CFx.wave.compute_wave_speeds(x,y,sigma,theta,depth_func,u_func,v_func,N_dof_2)
  File "/home1/04637/mdl2665/WAVEx/CFx/wave.py", line 213, in compute_wave_speeds
    c_out[wet_dofs_local,:],cph[wet_dofs_local],k[wet_dofs_local] = compute_wave_speeds_pointwise(x[wet_dofs_local],y[wet_dofs_local],sigma[wet_dofs_local],theta[wet_dofs_local],depth[wet_dofs_local],
IndexError: index 24600 is out of bounds for axis 0 with size 23575
Traceback (most recent call last):
  File "/home1/04637/mdl2665/WAVEx/main.py", line 259, in <module>
    c,dry_dofs_local,cph,k = CFx.wave.compute_wave_speeds(x,y,sigma,theta,depth_func,u_func,v_func,N_dof_2)
  File "/home1/04637/mdl2665/WAVEx/CFx/wave.py", line 213, in compute_wave_speeds
    c_out[wet_dofs_local,:],cph[wet_dofs_local],k[wet_dofs_local] = compute_wave_speeds_pointwise(x[wet_dofs_local],y[wet_dofs_local],sigma[wet_dofs_local],theta[wet_dofs_local],depth[wet_dofs_local],
IndexError: index 24600 is out of bounds for axis 0 with size 24600
Traceback (most recent call last):
  File "/home1/04637/mdl2665/WAVEx/main.py", line 259, in <module>
    c,dry_dofs_local,cph,k = CFx.wave.compute_wave_speeds(x,y,sigma,theta,depth_func,u_func,v_func,N_dof_2)
  File "/home1/04637/mdl2665/WAVEx/CFx/wave.py", line 213, in compute_wave_speeds
    c_out[wet_dofs_local,:],cph[wet_dofs_local],k[wet_dofs_local] = compute_wave_speeds_pointwise(x[wet_dofs_local],y[wet_dofs_local],sigma[wet_dofs_local],theta[wet_dofs_local],depth[wet_dofs_local],
IndexError: index 22550 is out of bounds for axis 0 with size 22550
Traceback (most recent call last):
  File "/home1/04637/mdl2665/WAVEx/main.py", line 259, in <module>
    c,dry_dofs_local,cph,k = CFx.wave.compute_wave_speeds(x,y,sigma,theta,depth_func,u_func,v_func,N_dof_2)
  File "/home1/04637/mdl2665/WAVEx/CFx/wave.py", line 213, in compute_wave_speeds
    c_out[wet_dofs_local,:],cph[wet_dofs_local],k[wet_dofs_local] = compute_wave_speeds_pointwise(x[wet_dofs_local],y[wet_dofs_local],sigma[wet_dofs_local],theta[wet_dofs_local],depth[wet_dofs_local],
IndexError: index 22550 is out of bounds for axis 0 with size 22550
Traceback (most recent call last):
  File "/home1/04637/mdl2665/WAVEx/main.py", line 259, in <module>
    c,dry_dofs_local,cph,k = CFx.wave.compute_wave_speeds(x,y,sigma,theta,depth_func,u_func,v_func,N_dof_2)
  File "/home1/04637/mdl2665/WAVEx/CFx/wave.py", line 213, in compute_wave_speeds
    c_out[wet_dofs_local,:],cph[wet_dofs_local],k[wet_dofs_local] = compute_wave_speeds_pointwise(x[wet_dofs_local],y[wet_dofs_local],sigma[wet_dofs_local],theta[wet_dofs_local],depth[wet_dofs_local],
IndexError: index 22550 is out of bounds for axis 0 with size 22550
Traceback (most recent call last):
  File "/home1/04637/mdl2665/WAVEx/main.py", line 259, in <module>
    c,dry_dofs_local,cph,k = CFx.wave.compute_wave_speeds(x,y,sigma,theta,depth_func,u_func,v_func,N_dof_2)
  File "/home1/04637/mdl2665/WAVEx/CFx/wave.py", line 213, in compute_wave_speeds
    c_out[wet_dofs_local,:],cph[wet_dofs_local],k[wet_dofs_local] = compute_wave_speeds_pointwise(x[wet_dofs_local],y[wet_dofs_local],sigma[wet_dofs_local],theta[wet_dofs_local],depth[wet_dofs_local],
IndexError: index 24600 is out of bounds for axis 0 with size 24600
Traceback (most recent call last):
  File "/home1/04637/mdl2665/WAVEx/main.py", line 259, in <module>
    c,dry_dofs_local,cph,k = CFx.wave.compute_wave_speeds(x,y,sigma,theta,depth_func,u_func,v_func,N_dof_2)
  File "/home1/04637/mdl2665/WAVEx/CFx/wave.py", line 213, in compute_wave_speeds
    c_out[wet_dofs_local,:],cph[wet_dofs_local],k[wet_dofs_local] = compute_wave_speeds_pointwise(x[wet_dofs_local],y[wet_dofs_local],sigma[wet_dofs_local],theta[wet_dofs_local],depth[wet_dofs_local],
IndexError: index 24600 is out of bounds for axis 0 with size 23575
Traceback (most recent call last):
  File "/home1/04637/mdl2665/WAVEx/main.py", line 259, in <module>
    c,dry_dofs_local,cph,k = CFx.wave.compute_wave_speeds(x,y,sigma,theta,depth_func,u_func,v_func,N_dof_2)
  File "/home1/04637/mdl2665/WAVEx/CFx/wave.py", line 213, in compute_wave_speeds
Traceback (most recent call last):
  File "/home1/04637/mdl2665/WAVEx/main.py", line 259, in <module>
    c,dry_dofs_local,cph,k = CFx.wave.compute_wave_speeds(x,y,sigma,theta,depth_func,u_func,v_func,N_dof_2)
  File "/home1/04637/mdl2665/WAVEx/CFx/wave.py", line 213, in compute_wave_speeds
    c_out[wet_dofs_local,:],cph[wet_dofs_local],k[wet_dofs_local] = compute_wave_speeds_pointwise(x[wet_dofs_local],y[wet_dofs_local],sigma[wet_dofs_local],theta[wet_dofs_local],depth[wet_dofs_local],
IndexError: index 24600 is out of bounds for axis 0 with size 24600
Traceback (most recent call last):
  File "/home1/04637/mdl2665/WAVEx/main.py", line 259, in <module>
    c,dry_dofs_local,cph,k = CFx.wave.compute_wave_speeds(x,y,sigma,theta,depth_func,u_func,v_func,N_dof_2)
  File "/home1/04637/mdl2665/WAVEx/CFx/wave.py", line 213, in compute_wave_speeds
    c_out[wet_dofs_local,:],cph[wet_dofs_local],k[wet_dofs_local] = compute_wave_speeds_pointwise(x[wet_dofs_local],y[wet_dofs_local],sigma[wet_dofs_local],theta[wet_dofs_local],depth[wet_dofs_local],
IndexError: index 25625 is out of bounds for axis 0 with size 25625
    c_out[wet_dofs_local,:],cph[wet_dofs_local],k[wet_dofs_local] = compute_wave_speeds_pointwise(x[wet_dofs_local],y[wet_dofs_local],sigma[wet_dofs_local],theta[wet_dofs_local],depth[wet_dofs_local],
IndexError: index 21525 is out of bounds for axis 0 with size 20500
Traceback (most recent call last):
  File "/home1/04637/mdl2665/WAVEx/main.py", line 259, in <module>
    c,dry_dofs_local,cph,k = CFx.wave.compute_wave_speeds(x,y,sigma,theta,depth_func,u_func,v_func,N_dof_2)
  File "/home1/04637/mdl2665/WAVEx/CFx/wave.py", line 213, in compute_wave_speeds
    c_out[wet_dofs_local,:],cph[wet_dofs_local],k[wet_dofs_local] = compute_wave_speeds_pointwise(x[wet_dofs_local],y[wet_dofs_local],sigma[wet_dofs_local],theta[wet_dofs_local],depth[wet_dofs_local],
IndexError: index 21525 is out of bounds for axis 0 with size 21525
Traceback (most recent call last):
  File "/home1/04637/mdl2665/WAVEx/main.py", line 259, in <module>
    c,dry_dofs_local,cph,k = CFx.wave.compute_wave_speeds(x,y,sigma,theta,depth_func,u_func,v_func,N_dof_2)
  File "/home1/04637/mdl2665/WAVEx/CFx/wave.py", line 213, in compute_wave_speeds
    c_out[wet_dofs_local,:],cph[wet_dofs_local],k[wet_dofs_local] = compute_wave_speeds_pointwise(x[wet_dofs_local],y[wet_dofs_local],sigma[wet_dofs_local],theta[wet_dofs_local],depth[wet_dofs_local],
IndexError: index 26650 is out of bounds for axis 0 with size 25625
Traceback (most recent call last):
  File "/home1/04637/mdl2665/WAVEx/main.py", line 259, in <module>
    c,dry_dofs_local,cph,k = CFx.wave.compute_wave_speeds(x,y,sigma,theta,depth_func,u_func,v_func,N_dof_2)
  File "/home1/04637/mdl2665/WAVEx/CFx/wave.py", line 213, in compute_wave_speeds
    c_out[wet_dofs_local,:],cph[wet_dofs_local],k[wet_dofs_local] = compute_wave_speeds_pointwise(x[wet_dofs_local],y[wet_dofs_local],sigma[wet_dofs_local],theta[wet_dofs_local],depth[wet_dofs_local],
IndexError: index 24600 is out of bounds for axis 0 with size 23575
Traceback (most recent call last):
  File "/home1/04637/mdl2665/WAVEx/main.py", line 259, in <module>
    c,dry_dofs_local,cph,k = CFx.wave.compute_wave_speeds(x,y,sigma,theta,depth_func,u_func,v_func,N_dof_2)
  File "/home1/04637/mdl2665/WAVEx/CFx/wave.py", line 213, in compute_wave_speeds
    c_out[wet_dofs_local,:],cph[wet_dofs_local],k[wet_dofs_local] = compute_wave_speeds_pointwise(x[wet_dofs_local],y[wet_dofs_local],sigma[wet_dofs_local],theta[wet_dofs_local],depth[wet_dofs_local],
IndexError: index 25625 is out of bounds for axis 0 with size 24600
Traceback (most recent call last):
  File "/home1/04637/mdl2665/WAVEx/main.py", line 259, in <module>
    c,dry_dofs_local,cph,k = CFx.wave.compute_wave_speeds(x,y,sigma,theta,depth_func,u_func,v_func,N_dof_2)
  File "/home1/04637/mdl2665/WAVEx/CFx/wave.py", line 213, in compute_wave_speeds
    c_out[wet_dofs_local,:],cph[wet_dofs_local],k[wet_dofs_local] = compute_wave_speeds_pointwise(x[wet_dofs_local],y[wet_dofs_local],sigma[wet_dofs_local],theta[wet_dofs_local],depth[wet_dofs_local],
IndexError: index 27675 is out of bounds for axis 0 with size 27675
Traceback (most recent call last):
  File "/home1/04637/mdl2665/WAVEx/main.py", line 259, in <module>
    c,dry_dofs_local,cph,k = CFx.wave.compute_wave_speeds(x,y,sigma,theta,depth_func,u_func,v_func,N_dof_2)
  File "/home1/04637/mdl2665/WAVEx/CFx/wave.py", line 213, in compute_wave_speeds
    c_out[wet_dofs_local,:],cph[wet_dofs_local],k[wet_dofs_local] = compute_wave_speeds_pointwise(x[wet_dofs_local],y[wet_dofs_local],sigma[wet_dofs_local],theta[wet_dofs_local],depth[wet_dofs_local],
IndexError: index 26650 is out of bounds for axis 0 with size 26650
Traceback (most recent call last):
  File "/home1/04637/mdl2665/WAVEx/main.py", line 259, in <module>
    c,dry_dofs_local,cph,k = CFx.wave.compute_wave_speeds(x,y,sigma,theta,depth_func,u_func,v_func,N_dof_2)
  File "/home1/04637/mdl2665/WAVEx/CFx/wave.py", line 213, in compute_wave_speeds
    c_out[wet_dofs_local,:],cph[wet_dofs_local],k[wet_dofs_local] = compute_wave_speeds_pointwise(x[wet_dofs_local],y[wet_dofs_local],sigma[wet_dofs_local],theta[wet_dofs_local],depth[wet_dofs_local],
IndexError: index 24600 is out of bounds for axis 0 with size 24600
Traceback (most recent call last):
  File "/home1/04637/mdl2665/WAVEx/main.py", line 259, in <module>
Traceback (most recent call last):
  File "/home1/04637/mdl2665/WAVEx/main.py", line 259, in <module>
    c,dry_dofs_local,cph,k = CFx.wave.compute_wave_speeds(x,y,sigma,theta,depth_func,u_func,v_func,N_dof_2)
  File "/home1/04637/mdl2665/WAVEx/CFx/wave.py", line 213, in compute_wave_speeds
    c_out[wet_dofs_local,:],cph[wet_dofs_local],k[wet_dofs_local] = compute_wave_speeds_pointwise(x[wet_dofs_local],y[wet_dofs_local],sigma[wet_dofs_local],theta[wet_dofs_local],depth[wet_dofs_local],
IndexError: index 25625 is out of bounds for axis 0 with size 25625
Traceback (most recent call last):
  File "/home1/04637/mdl2665/WAVEx/main.py", line 259, in <module>
    c,dry_dofs_local,cph,k = CFx.wave.compute_wave_speeds(x,y,sigma,theta,depth_func,u_func,v_func,N_dof_2)
  File "/home1/04637/mdl2665/WAVEx/CFx/wave.py", line 213, in compute_wave_speeds
    c_out[wet_dofs_local,:],cph[wet_dofs_local],k[wet_dofs_local] = compute_wave_speeds_pointwise(x[wet_dofs_local],y[wet_dofs_local],sigma[wet_dofs_local],theta[wet_dofs_local],depth[wet_dofs_local],
IndexError: index 26650 is out of bounds for axis 0 with size 25625
Traceback (most recent call last):
  File "/home1/04637/mdl2665/WAVEx/main.py", line 259, in <module>
    c,dry_dofs_local,cph,k = CFx.wave.compute_wave_speeds(x,y,sigma,theta,depth_func,u_func,v_func,N_dof_2)
  File "/home1/04637/mdl2665/WAVEx/CFx/wave.py", line 213, in compute_wave_speeds
    c_out[wet_dofs_local,:],cph[wet_dofs_local],k[wet_dofs_local] = compute_wave_speeds_pointwise(x[wet_dofs_local],y[wet_dofs_local],sigma[wet_dofs_local],theta[wet_dofs_local],depth[wet_dofs_local],
IndexError: index 24600 is out of bounds for axis 0 with size 24600
Traceback (most recent call last):
  File "/home1/04637/mdl2665/WAVEx/main.py", line 259, in <module>
    c,dry_dofs_local,cph,k = CFx.wave.compute_wave_speeds(x,y,sigma,theta,depth_func,u_func,v_func,N_dof_2)
  File "/home1/04637/mdl2665/WAVEx/CFx/wave.py", line 213, in compute_wave_speeds
    c_out[wet_dofs_local,:],cph[wet_dofs_local],k[wet_dofs_local] = compute_wave_speeds_pointwise(x[wet_dofs_local],y[wet_dofs_local],sigma[wet_dofs_local],theta[wet_dofs_local],depth[wet_dofs_local],
IndexError: index 21525 is out of bounds for axis 0 with size 20500
Traceback (most recent call last):
  File "/home1/04637/mdl2665/WAVEx/main.py", line 259, in <module>
    c,dry_dofs_local,cph,k = CFx.wave.compute_wave_speeds(x,y,sigma,theta,depth_func,u_func,v_func,N_dof_2)
  File "/home1/04637/mdl2665/WAVEx/CFx/wave.py", line 213, in compute_wave_speeds
    c_out[wet_dofs_local,:],cph[wet_dofs_local],k[wet_dofs_local] = compute_wave_speeds_pointwise(x[wet_dofs_local],y[wet_dofs_local],sigma[wet_dofs_local],theta[wet_dofs_local],depth[wet_dofs_local],
IndexError: index 26650 is out of bounds for axis 0 with size 26650
Traceback (most recent call last):
  File "/home1/04637/mdl2665/WAVEx/main.py", line 259, in <module>
    c,dry_dofs_local,cph,k = CFx.wave.compute_wave_speeds(x,y,sigma,theta,depth_func,u_func,v_func,N_dof_2)
  File "/home1/04637/mdl2665/WAVEx/CFx/wave.py", line 213, in compute_wave_speeds
    c_out[wet_dofs_local,:],cph[wet_dofs_local],k[wet_dofs_local] = compute_wave_speeds_pointwise(x[wet_dofs_local],y[wet_dofs_local],sigma[wet_dofs_local],theta[wet_dofs_local],depth[wet_dofs_local],
IndexError: index 25625 is out of bounds for axis 0 with size 25625
    c,dry_dofs_local,cph,k = CFx.wave.compute_wave_speeds(x,y,sigma,theta,depth_func,u_func,v_func,N_dof_2)
  File "/home1/04637/mdl2665/WAVEx/CFx/wave.py", line 213, in compute_wave_speeds
    c_out[wet_dofs_local,:],cph[wet_dofs_local],k[wet_dofs_local] = compute_wave_speeds_pointwise(x[wet_dofs_local],y[wet_dofs_local],sigma[wet_dofs_local],theta[wet_dofs_local],depth[wet_dofs_local],
IndexError: index 25625 is out of bounds for axis 0 with size 23575
Traceback (most recent call last):
  File "/home1/04637/mdl2665/WAVEx/main.py", line 259, in <module>
    c,dry_dofs_local,cph,k = CFx.wave.compute_wave_speeds(x,y,sigma,theta,depth_func,u_func,v_func,N_dof_2)
  File "/home1/04637/mdl2665/WAVEx/CFx/wave.py", line 213, in compute_wave_speeds
    c_out[wet_dofs_local,:],cph[wet_dofs_local],k[wet_dofs_local] = compute_wave_speeds_pointwise(x[wet_dofs_local],y[wet_dofs_local],sigma[wet_dofs_local],theta[wet_dofs_local],depth[wet_dofs_local],
IndexError: index 21525 is out of bounds for axis 0 with size 21525
Traceback (most recent call last):
  File "/home1/04637/mdl2665/WAVEx/main.py", line 259, in <module>
    c,dry_dofs_local,cph,k = CFx.wave.compute_wave_speeds(x,y,sigma,theta,depth_func,u_func,v_func,N_dof_2)
  File "/home1/04637/mdl2665/WAVEx/CFx/wave.py", line 213, in compute_wave_speeds
    c_out[wet_dofs_local,:],cph[wet_dofs_local],k[wet_dofs_local] = compute_wave_speeds_pointwise(x[wet_dofs_local],y[wet_dofs_local],sigma[wet_dofs_local],theta[wet_dofs_local],depth[wet_dofs_local],
IndexError: index 24600 is out of bounds for axis 0 with size 24600
Traceback (most recent call last):
  File "/home1/04637/mdl2665/WAVEx/main.py", line 259, in <module>
    c,dry_dofs_local,cph,k = CFx.wave.compute_wave_speeds(x,y,sigma,theta,depth_func,u_func,v_func,N_dof_2)
  File "/home1/04637/mdl2665/WAVEx/CFx/wave.py", line 213, in compute_wave_speeds
    c_out[wet_dofs_local,:],cph[wet_dofs_local],k[wet_dofs_local] = compute_wave_speeds_pointwise(x[wet_dofs_local],y[wet_dofs_local],sigma[wet_dofs_local],theta[wet_dofs_local],depth[wet_dofs_local],
IndexError: index 24600 is out of bounds for axis 0 with size 23575
Traceback (most recent call last):
  File "/home1/04637/mdl2665/WAVEx/main.py", line 259, in <module>
    c,dry_dofs_local,cph,k = CFx.wave.compute_wave_speeds(x,y,sigma,theta,depth_func,u_func,v_func,N_dof_2)
  File "/home1/04637/mdl2665/WAVEx/CFx/wave.py", line 213, in compute_wave_speeds
    c_out[wet_dofs_local,:],cph[wet_dofs_local],k[wet_dofs_local] = compute_wave_speeds_pointwise(x[wet_dofs_local],y[wet_dofs_local],sigma[wet_dofs_local],theta[wet_dofs_local],depth[wet_dofs_local],
IndexError: index 24600 is out of bounds for axis 0 with size 24600
Traceback (most recent call last):
  File "/home1/04637/mdl2665/WAVEx/main.py", line 259, in <module>
    c,dry_dofs_local,cph,k = CFx.wave.compute_wave_speeds(x,y,sigma,theta,depth_func,u_func,v_func,N_dof_2)
  File "/home1/04637/mdl2665/WAVEx/CFx/wave.py", line 213, in compute_wave_speeds
    c_out[wet_dofs_local,:],cph[wet_dofs_local],k[wet_dofs_local] = compute_wave_speeds_pointwise(x[wet_dofs_local],y[wet_dofs_local],sigma[wet_dofs_local],theta[wet_dofs_local],depth[wet_dofs_local],
IndexError: index 25625 is out of bounds for axis 0 with size 25625
Traceback (most recent call last):
  File "/home1/04637/mdl2665/WAVEx/main.py", line 259, in <module>
    c,dry_dofs_local,cph,k = CFx.wave.compute_wave_speeds(x,y,sigma,theta,depth_func,u_func,v_func,N_dof_2)
  File "/home1/04637/mdl2665/WAVEx/CFx/wave.py", line 213, in compute_wave_speeds
    c_out[wet_dofs_local,:],cph[wet_dofs_local],k[wet_dofs_local] = compute_wave_speeds_pointwise(x[wet_dofs_local],y[wet_dofs_local],sigma[wet_dofs_local],theta[wet_dofs_local],depth[wet_dofs_local],
IndexError: index 25625 is out of bounds for axis 0 with size 25625
Traceback (most recent call last):
  File "/home1/04637/mdl2665/WAVEx/main.py", line 259, in <module>
    c,dry_dofs_local,cph,k = CFx.wave.compute_wave_speeds(x,y,sigma,theta,depth_func,u_func,v_func,N_dof_2)
  File "/home1/04637/mdl2665/WAVEx/CFx/wave.py", line 213, in compute_wave_speeds
    c_out[wet_dofs_local,:],cph[wet_dofs_local],k[wet_dofs_local] = compute_wave_speeds_pointwise(x[wet_dofs_local],y[wet_dofs_local],sigma[wet_dofs_local],theta[wet_dofs_local],depth[wet_dofs_local],
IndexError: index 23575 is out of bounds for axis 0 with size 23575
Traceback (most recent call last):
  File "/home1/04637/mdl2665/WAVEx/main.py", line 259, in <module>
    c,dry_dofs_local,cph,k = CFx.wave.compute_wave_speeds(x,y,sigma,theta,depth_func,u_func,v_func,N_dof_2)
  File "/home1/04637/mdl2665/WAVEx/CFx/wave.py", line 213, in compute_wave_speeds
    c_out[wet_dofs_local,:],cph[wet_dofs_local],k[wet_dofs_local] = compute_wave_speeds_pointwise(x[wet_dofs_local],y[wet_dofs_local],sigma[wet_dofs_local],theta[wet_dofs_local],depth[wet_dofs_local],
IndexError: index 25625 is out of bounds for axis 0 with size 25625
Traceback (most recent call last):
  File "/home1/04637/mdl2665/WAVEx/main.py", line 259, in <module>
    c,dry_dofs_local,cph,k = CFx.wave.compute_wave_speeds(x,y,sigma,theta,depth_func,u_func,v_func,N_dof_2)
  File "/home1/04637/mdl2665/WAVEx/CFx/wave.py", line 213, in compute_wave_speeds
    c_out[wet_dofs_local,:],cph[wet_dofs_local],k[wet_dofs_local] = compute_wave_speeds_pointwise(x[wet_dofs_local],y[wet_dofs_local],sigma[wet_dofs_local],theta[wet_dofs_local],depth[wet_dofs_local],
IndexError: index 21525 is out of bounds for axis 0 with size 21525
Traceback (most recent call last):
  File "/home1/04637/mdl2665/WAVEx/main.py", line 259, in <module>
    c,dry_dofs_local,cph,k = CFx.wave.compute_wave_speeds(x,y,sigma,theta,depth_func,u_func,v_func,N_dof_2)
  File "/home1/04637/mdl2665/WAVEx/CFx/wave.py", line 213, in compute_wave_speeds
    c_out[wet_dofs_local,:],cph[wet_dofs_local],k[wet_dofs_local] = compute_wave_speeds_pointwise(x[wet_dofs_local],y[wet_dofs_local],sigma[wet_dofs_local],theta[wet_dofs_local],depth[wet_dofs_local],
IndexError: index 24600 is out of bounds for axis 0 with size 24600
Traceback (most recent call last):
  File "/home1/04637/mdl2665/WAVEx/main.py", line 259, in <module>
    c,dry_dofs_local,cph,k = CFx.wave.compute_wave_speeds(x,y,sigma,theta,depth_func,u_func,v_func,N_dof_2)
  File "/home1/04637/mdl2665/WAVEx/CFx/wave.py", line 213, in compute_wave_speeds
    c_out[wet_dofs_local,:],cph[wet_dofs_local],k[wet_dofs_local] = compute_wave_speeds_pointwise(x[wet_dofs_local],y[wet_dofs_local],sigma[wet_dofs_local],theta[wet_dofs_local],depth[wet_dofs_local],
IndexError: index 24600 is out of bounds for axis 0 with size 24600
Traceback (most recent call last):
  File "/home1/04637/mdl2665/WAVEx/main.py", line 259, in <module>
    c,dry_dofs_local,cph,k = CFx.wave.compute_wave_speeds(x,y,sigma,theta,depth_func,u_func,v_func,N_dof_2)
  File "/home1/04637/mdl2665/WAVEx/CFx/wave.py", line 213, in compute_wave_speeds
    c_out[wet_dofs_local,:],cph[wet_dofs_local],k[wet_dofs_local] = compute_wave_speeds_pointwise(x[wet_dofs_local],y[wet_dofs_local],sigma[wet_dofs_local],theta[wet_dofs_local],depth[wet_dofs_local],
IndexError: index 20500 is out of bounds for axis 0 with size 20500
Traceback (most recent call last):
  File "/home1/04637/mdl2665/WAVEx/main.py", line 259, in <module>
    c,dry_dofs_local,cph,k = CFx.wave.compute_wave_speeds(x,y,sigma,theta,depth_func,u_func,v_func,N_dof_2)
  File "/home1/04637/mdl2665/WAVEx/CFx/wave.py", line 213, in compute_wave_speeds
    c_out[wet_dofs_local,:],cph[wet_dofs_local],k[wet_dofs_local] = compute_wave_speeds_pointwise(x[wet_dofs_local],y[wet_dofs_local],sigma[wet_dofs_local],theta[wet_dofs_local],depth[wet_dofs_local],
IndexError: index 22550 is out of bounds for axis 0 with size 22550
    c_out[wet_dofs_local,:],cph[wet_dofs_local],k[wet_dofs_local] = compute_wave_speeds_pointwise(x[wet_dofs_local],y[wet_dofs_local],sigma[wet_dofs_local],theta[wet_dofs_local],depth[wet_dofs_local],
IndexError: index 19475 is out of bounds for axis 0 with size 19475
Traceback (most recent call last):
  File "/home1/04637/mdl2665/WAVEx/main.py", line 259, in <module>
    c,dry_dofs_local,cph,k = CFx.wave.compute_wave_speeds(x,y,sigma,theta,depth_func,u_func,v_func,N_dof_2)
  File "/home1/04637/mdl2665/WAVEx/CFx/wave.py", line 213, in compute_wave_speeds
    c_out[wet_dofs_local,:],cph[wet_dofs_local],k[wet_dofs_local] = compute_wave_speeds_pointwise(x[wet_dofs_local],y[wet_dofs_local],sigma[wet_dofs_local],theta[wet_dofs_local],depth[wet_dofs_local],
IndexError: index 24600 is out of bounds for axis 0 with size 24600
Traceback (most recent call last):
  File "/home1/04637/mdl2665/WAVEx/main.py", line 259, in <module>
    c,dry_dofs_local,cph,k = CFx.wave.compute_wave_speeds(x,y,sigma,theta,depth_func,u_func,v_func,N_dof_2)
  File "/home1/04637/mdl2665/WAVEx/CFx/wave.py", line 213, in compute_wave_speeds
    c_out[wet_dofs_local,:],cph[wet_dofs_local],k[wet_dofs_local] = compute_wave_speeds_pointwise(x[wet_dofs_local],y[wet_dofs_local],sigma[wet_dofs_local],theta[wet_dofs_local],depth[wet_dofs_local],
IndexError: index 23575 is out of bounds for axis 0 with size 23575
Traceback (most recent call last):
  File "/home1/04637/mdl2665/WAVEx/main.py", line 259, in <module>
    c,dry_dofs_local,cph,k = CFx.wave.compute_wave_speeds(x,y,sigma,theta,depth_func,u_func,v_func,N_dof_2)
  File "/home1/04637/mdl2665/WAVEx/CFx/wave.py", line 213, in compute_wave_speeds
    c_out[wet_dofs_local,:],cph[wet_dofs_local],k[wet_dofs_local] = compute_wave_speeds_pointwise(x[wet_dofs_local],y[wet_dofs_local],sigma[wet_dofs_local],theta[wet_dofs_local],depth[wet_dofs_local],
IndexError: index 24600 is out of bounds for axis 0 with size 24600
Traceback (most recent call last):
  File "/home1/04637/mdl2665/WAVEx/main.py", line 259, in <module>
    c,dry_dofs_local,cph,k = CFx.wave.compute_wave_speeds(x,y,sigma,theta,depth_func,u_func,v_func,N_dof_2)
  File "/home1/04637/mdl2665/WAVEx/CFx/wave.py", line 213, in compute_wave_speeds
    c_out[wet_dofs_local,:],cph[wet_dofs_local],k[wet_dofs_local] = compute_wave_speeds_pointwise(x[wet_dofs_local],y[wet_dofs_local],sigma[wet_dofs_local],theta[wet_dofs_local],depth[wet_dofs_local],
IndexError: index 23575 is out of bounds for axis 0 with size 23575
Traceback (most recent call last):
  File "/home1/04637/mdl2665/WAVEx/main.py", line 259, in <module>
    c,dry_dofs_local,cph,k = CFx.wave.compute_wave_speeds(x,y,sigma,theta,depth_func,u_func,v_func,N_dof_2)
  File "/home1/04637/mdl2665/WAVEx/CFx/wave.py", line 213, in compute_wave_speeds
    c_out[wet_dofs_local,:],cph[wet_dofs_local],k[wet_dofs_local] = compute_wave_speeds_pointwise(x[wet_dofs_local],y[wet_dofs_local],sigma[wet_dofs_local],theta[wet_dofs_local],depth[wet_dofs_local],
IndexError: index 22550 is out of bounds for axis 0 with size 22550
Traceback (most recent call last):
  File "/home1/04637/mdl2665/WAVEx/main.py", line 259, in <module>
    c,dry_dofs_local,cph,k = CFx.wave.compute_wave_speeds(x,y,sigma,theta,depth_func,u_func,v_func,N_dof_2)
  File "/home1/04637/mdl2665/WAVEx/CFx/wave.py", line 213, in compute_wave_speeds
    c_out[wet_dofs_local,:],cph[wet_dofs_local],k[wet_dofs_local] = compute_wave_speeds_pointwise(x[wet_dofs_local],y[wet_dofs_local],sigma[wet_dofs_local],theta[wet_dofs_local],depth[wet_dofs_local],
IndexError: index 23575 is out of bounds for axis 0 with size 23575
Traceback (most recent call last):
  File "/home1/04637/mdl2665/WAVEx/main.py", line 259, in <module>
    c,dry_dofs_local,cph,k = CFx.wave.compute_wave_speeds(x,y,sigma,theta,depth_func,u_func,v_func,N_dof_2)
  File "/home1/04637/mdl2665/WAVEx/CFx/wave.py", line 213, in compute_wave_speeds
    c_out[wet_dofs_local,:],cph[wet_dofs_local],k[wet_dofs_local] = compute_wave_speeds_pointwise(x[wet_dofs_local],y[wet_dofs_local],sigma[wet_dofs_local],theta[wet_dofs_local],depth[wet_dofs_local],
IndexError: index 22550 is out of bounds for axis 0 with size 22550
Traceback (most recent call last):
  File "/home1/04637/mdl2665/WAVEx/main.py", line 259, in <module>
    c,dry_dofs_local,cph,k = CFx.wave.compute_wave_speeds(x,y,sigma,theta,depth_func,u_func,v_func,N_dof_2)
  File "/home1/04637/mdl2665/WAVEx/CFx/wave.py", line 213, in compute_wave_speeds
    c_out[wet_dofs_local,:],cph[wet_dofs_local],k[wet_dofs_local] = compute_wave_speeds_pointwise(x[wet_dofs_local],y[wet_dofs_local],sigma[wet_dofs_local],theta[wet_dofs_local],depth[wet_dofs_local],
IndexError: index 24600 is out of bounds for axis 0 with size 24600
Traceback (most recent call last):
  File "/home1/04637/mdl2665/WAVEx/main.py", line 259, in <module>
    c,dry_dofs_local,cph,k = CFx.wave.compute_wave_speeds(x,y,sigma,theta,depth_func,u_func,v_func,N_dof_2)
  File "/home1/04637/mdl2665/WAVEx/CFx/wave.py", line 213, in compute_wave_speeds
    c_out[wet_dofs_local,:],cph[wet_dofs_local],k[wet_dofs_local] = compute_wave_speeds_pointwise(x[wet_dofs_local],y[wet_dofs_local],sigma[wet_dofs_local],theta[wet_dofs_local],depth[wet_dofs_local],
IndexError: index 21525 is out of bounds for axis 0 with size 21525
Traceback (most recent call last):
  File "/home1/04637/mdl2665/WAVEx/main.py", line 259, in <module>
    c,dry_dofs_local,cph,k = CFx.wave.compute_wave_speeds(x,y,sigma,theta,depth_func,u_func,v_func,N_dof_2)
  File "/home1/04637/mdl2665/WAVEx/CFx/wave.py", line 213, in compute_wave_speeds
    c_out[wet_dofs_local,:],cph[wet_dofs_local],k[wet_dofs_local] = compute_wave_speeds_pointwise(x[wet_dofs_local],y[wet_dofs_local],sigma[wet_dofs_local],theta[wet_dofs_local],depth[wet_dofs_local],
IndexError: index 22550 is out of bounds for axis 0 with size 22550
Traceback (most recent call last):
  File "/home1/04637/mdl2665/WAVEx/main.py", line 259, in <module>
    c,dry_dofs_local,cph,k = CFx.wave.compute_wave_speeds(x,y,sigma,theta,depth_func,u_func,v_func,N_dof_2)
  File "/home1/04637/mdl2665/WAVEx/CFx/wave.py", line 213, in compute_wave_speeds
    c_out[wet_dofs_local,:],cph[wet_dofs_local],k[wet_dofs_local] = compute_wave_speeds_pointwise(x[wet_dofs_local],y[wet_dofs_local],sigma[wet_dofs_local],theta[wet_dofs_local],depth[wet_dofs_local],
IndexError: index 23575 is out of bounds for axis 0 with size 23575
Traceback (most recent call last):
  File "/home1/04637/mdl2665/WAVEx/main.py", line 259, in <module>
    c,dry_dofs_local,cph,k = CFx.wave.compute_wave_speeds(x,y,sigma,theta,depth_func,u_func,v_func,N_dof_2)
  File "/home1/04637/mdl2665/WAVEx/CFx/wave.py", line 213, in compute_wave_speeds
    c_out[wet_dofs_local,:],cph[wet_dofs_local],k[wet_dofs_local] = compute_wave_speeds_pointwise(x[wet_dofs_local],y[wet_dofs_local],sigma[wet_dofs_local],theta[wet_dofs_local],depth[wet_dofs_local],
IndexError: index 27675 is out of bounds for axis 0 with size 27675
Traceback (most recent call last):
  File "/home1/04637/mdl2665/WAVEx/main.py", line 259, in <module>
    c,dry_dofs_local,cph,k = CFx.wave.compute_wave_speeds(x,y,sigma,theta,depth_func,u_func,v_func,N_dof_2)
  File "/home1/04637/mdl2665/WAVEx/CFx/wave.py", line 213, in compute_wave_speeds
    c_out[wet_dofs_local,:],cph[wet_dofs_local],k[wet_dofs_local] = compute_wave_speeds_pointwise(x[wet_dofs_local],y[wet_dofs_local],sigma[wet_dofs_local],theta[wet_dofs_local],depth[wet_dofs_local],
IndexError: index 25625 is out of bounds for axis 0 with size 25625
Traceback (most recent call last):
  File "/home1/04637/mdl2665/WAVEx/main.py", line 259, in <module>
    c,dry_dofs_local,cph,k = CFx.wave.compute_wave_speeds(x,y,sigma,theta,depth_func,u_func,v_func,N_dof_2)
  File "/home1/04637/mdl2665/WAVEx/CFx/wave.py", line 213, in compute_wave_speeds
    c_out[wet_dofs_local,:],cph[wet_dofs_local],k[wet_dofs_local] = compute_wave_speeds_pointwise(x[wet_dofs_local],y[wet_dofs_local],sigma[wet_dofs_local],theta[wet_dofs_local],depth[wet_dofs_local],
IndexError: index 22550 is out of bounds for axis 0 with size 22550
Traceback (most recent call last):
  File "/home1/04637/mdl2665/WAVEx/main.py", line 259, in <module>
    c,dry_dofs_local,cph,k = CFx.wave.compute_wave_speeds(x,y,sigma,theta,depth_func,u_func,v_func,N_dof_2)
  File "/home1/04637/mdl2665/WAVEx/CFx/wave.py", line 213, in compute_wave_speeds
    c_out[wet_dofs_local,:],cph[wet_dofs_local],k[wet_dofs_local] = compute_wave_speeds_pointwise(x[wet_dofs_local],y[wet_dofs_local],sigma[wet_dofs_local],theta[wet_dofs_local],depth[wet_dofs_local],
IndexError: index 24600 is out of bounds for axis 0 with size 24600
Traceback (most recent call last):
  File "/home1/04637/mdl2665/WAVEx/main.py", line 259, in <module>
    c,dry_dofs_local,cph,k = CFx.wave.compute_wave_speeds(x,y,sigma,theta,depth_func,u_func,v_func,N_dof_2)
  File "/home1/04637/mdl2665/WAVEx/CFx/wave.py", line 213, in compute_wave_speeds
    c_out[wet_dofs_local,:],cph[wet_dofs_local],k[wet_dofs_local] = compute_wave_speeds_pointwise(x[wet_dofs_local],y[wet_dofs_local],sigma[wet_dofs_local],theta[wet_dofs_local],depth[wet_dofs_local],
IndexError: index 24600 is out of bounds for axis 0 with size 24600
Traceback (most recent call last):
  File "/home1/04637/mdl2665/WAVEx/main.py", line 259, in <module>
    c,dry_dofs_local,cph,k = CFx.wave.compute_wave_speeds(x,y,sigma,theta,depth_func,u_func,v_func,N_dof_2)
  File "/home1/04637/mdl2665/WAVEx/CFx/wave.py", line 213, in compute_wave_speeds
    c_out[wet_dofs_local,:],cph[wet_dofs_local],k[wet_dofs_local] = compute_wave_speeds_pointwise(x[wet_dofs_local],y[wet_dofs_local],sigma[wet_dofs_local],theta[wet_dofs_local],depth[wet_dofs_local],
IndexError: index 23575 is out of bounds for axis 0 with size 23575
Traceback (most recent call last):
  File "/home1/04637/mdl2665/WAVEx/main.py", line 259, in <module>
Traceback (most recent call last):
  File "/home1/04637/mdl2665/WAVEx/main.py", line 259, in <module>
    c,dry_dofs_local,cph,k = CFx.wave.compute_wave_speeds(x,y,sigma,theta,depth_func,u_func,v_func,N_dof_2)
  File "/home1/04637/mdl2665/WAVEx/CFx/wave.py", line 213, in compute_wave_speeds
    c_out[wet_dofs_local,:],cph[wet_dofs_local],k[wet_dofs_local] = compute_wave_speeds_pointwise(x[wet_dofs_local],y[wet_dofs_local],sigma[wet_dofs_local],theta[wet_dofs_local],depth[wet_dofs_local],
IndexError: index 23575 is out of bounds for axis 0 with size 23575
Traceback (most recent call last):
  File "/home1/04637/mdl2665/WAVEx/main.py", line 259, in <module>
Traceback (most recent call last):
  File "/home1/04637/mdl2665/WAVEx/main.py", line 259, in <module>
    c,dry_dofs_local,cph,k = CFx.wave.compute_wave_speeds(x,y,sigma,theta,depth_func,u_func,v_func,N_dof_2)
  File "/home1/04637/mdl2665/WAVEx/CFx/wave.py", line 213, in compute_wave_speeds
    c_out[wet_dofs_local,:],cph[wet_dofs_local],k[wet_dofs_local] = compute_wave_speeds_pointwise(x[wet_dofs_local],y[wet_dofs_local],sigma[wet_dofs_local],theta[wet_dofs_local],depth[wet_dofs_local],
IndexError: index 24600 is out of bounds for axis 0 with size 24600
Traceback (most recent call last):
  File "/home1/04637/mdl2665/WAVEx/main.py", line 259, in <module>
    c,dry_dofs_local,cph,k = CFx.wave.compute_wave_speeds(x,y,sigma,theta,depth_func,u_func,v_func,N_dof_2)
  File "/home1/04637/mdl2665/WAVEx/CFx/wave.py", line 213, in compute_wave_speeds
    c_out[wet_dofs_local,:],cph[wet_dofs_local],k[wet_dofs_local] = compute_wave_speeds_pointwise(x[wet_dofs_local],y[wet_dofs_local],sigma[wet_dofs_local],theta[wet_dofs_local],depth[wet_dofs_local],
IndexError: index 23575 is out of bounds for axis 0 with size 23575
Traceback (most recent call last):
  File "/home1/04637/mdl2665/WAVEx/main.py", line 259, in <module>
    c,dry_dofs_local,cph,k = CFx.wave.compute_wave_speeds(x,y,sigma,theta,depth_func,u_func,v_func,N_dof_2)
  File "/home1/04637/mdl2665/WAVEx/CFx/wave.py", line 213, in compute_wave_speeds
    c_out[wet_dofs_local,:],cph[wet_dofs_local],k[wet_dofs_local] = compute_wave_speeds_pointwise(x[wet_dofs_local],y[wet_dofs_local],sigma[wet_dofs_local],theta[wet_dofs_local],depth[wet_dofs_local],
IndexError: index 23575 is out of bounds for axis 0 with size 23575
Traceback (most recent call last):
  File "/home1/04637/mdl2665/WAVEx/main.py", line 259, in <module>
    c,dry_dofs_local,cph,k = CFx.wave.compute_wave_speeds(x,y,sigma,theta,depth_func,u_func,v_func,N_dof_2)
  File "/home1/04637/mdl2665/WAVEx/CFx/wave.py", line 213, in compute_wave_speeds
    c_out[wet_dofs_local,:],cph[wet_dofs_local],k[wet_dofs_local] = compute_wave_speeds_pointwise(x[wet_dofs_local],y[wet_dofs_local],sigma[wet_dofs_local],theta[wet_dofs_local],depth[wet_dofs_local],
IndexError: index 22550 is out of bounds for axis 0 with size 22550
Traceback (most recent call last):
  File "/home1/04637/mdl2665/WAVEx/main.py", line 259, in <module>
    c,dry_dofs_local,cph,k = CFx.wave.compute_wave_speeds(x,y,sigma,theta,depth_func,u_func,v_func,N_dof_2)
  File "/home1/04637/mdl2665/WAVEx/CFx/wave.py", line 213, in compute_wave_speeds
    c_out[wet_dofs_local,:],cph[wet_dofs_local],k[wet_dofs_local] = compute_wave_speeds_pointwise(x[wet_dofs_local],y[wet_dofs_local],sigma[wet_dofs_local],theta[wet_dofs_local],depth[wet_dofs_local],
IndexError: index 25625 is out of bounds for axis 0 with size 25625
Traceback (most recent call last):
  File "/home1/04637/mdl2665/WAVEx/main.py", line 259, in <module>
Traceback (most recent call last):
  File "/home1/04637/mdl2665/WAVEx/main.py", line 259, in <module>
    c,dry_dofs_local,cph,k = CFx.wave.compute_wave_speeds(x,y,sigma,theta,depth_func,u_func,v_func,N_dof_2)
  File "/home1/04637/mdl2665/WAVEx/CFx/wave.py", line 213, in compute_wave_speeds
    c_out[wet_dofs_local,:],cph[wet_dofs_local],k[wet_dofs_local] = compute_wave_speeds_pointwise(x[wet_dofs_local],y[wet_dofs_local],sigma[wet_dofs_local],theta[wet_dofs_local],depth[wet_dofs_local],
IndexError: index 22550 is out of bounds for axis 0 with size 22550
Traceback (most recent call last):
  File "/home1/04637/mdl2665/WAVEx/main.py", line 259, in <module>
Traceback (most recent call last):
  File "/home1/04637/mdl2665/WAVEx/main.py", line 259, in <module>
    c,dry_dofs_local,cph,k = CFx.wave.compute_wave_speeds(x,y,sigma,theta,depth_func,u_func,v_func,N_dof_2)
  File "/home1/04637/mdl2665/WAVEx/CFx/wave.py", line 213, in compute_wave_speeds
    c_out[wet_dofs_local,:],cph[wet_dofs_local],k[wet_dofs_local] = compute_wave_speeds_pointwise(x[wet_dofs_local],y[wet_dofs_local],sigma[wet_dofs_local],theta[wet_dofs_local],depth[wet_dofs_local],
IndexError: index 23575 is out of bounds for axis 0 with size 23575
    c_out[wet_dofs_local,:],cph[wet_dofs_local],k[wet_dofs_local] = compute_wave_speeds_pointwise(x[wet_dofs_local],y[wet_dofs_local],sigma[wet_dofs_local],theta[wet_dofs_local],depth[wet_dofs_local],
IndexError: index 21525 is out of bounds for axis 0 with size 21525
Traceback (most recent call last):
  File "/home1/04637/mdl2665/WAVEx/main.py", line 259, in <module>
    c,dry_dofs_local,cph,k = CFx.wave.compute_wave_speeds(x,y,sigma,theta,depth_func,u_func,v_func,N_dof_2)
  File "/home1/04637/mdl2665/WAVEx/CFx/wave.py", line 213, in compute_wave_speeds
    c_out[wet_dofs_local,:],cph[wet_dofs_local],k[wet_dofs_local] = compute_wave_speeds_pointwise(x[wet_dofs_local],y[wet_dofs_local],sigma[wet_dofs_local],theta[wet_dofs_local],depth[wet_dofs_local],
IndexError: index 23575 is out of bounds for axis 0 with size 21525
    c,dry_dofs_local,cph,k = CFx.wave.compute_wave_speeds(x,y,sigma,theta,depth_func,u_func,v_func,N_dof_2)
  File "/home1/04637/mdl2665/WAVEx/CFx/wave.py", line 213, in compute_wave_speeds
Traceback (most recent call last):
  File "/home1/04637/mdl2665/WAVEx/main.py", line 259, in <module>
    c,dry_dofs_local,cph,k = CFx.wave.compute_wave_speeds(x,y,sigma,theta,depth_func,u_func,v_func,N_dof_2)
  File "/home1/04637/mdl2665/WAVEx/CFx/wave.py", line 213, in compute_wave_speeds
    c_out[wet_dofs_local,:],cph[wet_dofs_local],k[wet_dofs_local] = compute_wave_speeds_pointwise(x[wet_dofs_local],y[wet_dofs_local],sigma[wet_dofs_local],theta[wet_dofs_local],depth[wet_dofs_local],
IndexError: index 26650 is out of bounds for axis 0 with size 26650
    c,dry_dofs_local,cph,k = CFx.wave.compute_wave_speeds(x,y,sigma,theta,depth_func,u_func,v_func,N_dof_2)
  File "/home1/04637/mdl2665/WAVEx/CFx/wave.py", line 213, in compute_wave_speeds
Traceback (most recent call last):
  File "/home1/04637/mdl2665/WAVEx/main.py", line 259, in <module>
    c,dry_dofs_local,cph,k = CFx.wave.compute_wave_speeds(x,y,sigma,theta,depth_func,u_func,v_func,N_dof_2)
  File "/home1/04637/mdl2665/WAVEx/CFx/wave.py", line 213, in compute_wave_speeds
    c_out[wet_dofs_local,:],cph[wet_dofs_local],k[wet_dofs_local] = compute_wave_speeds_pointwise(x[wet_dofs_local],y[wet_dofs_local],sigma[wet_dofs_local],theta[wet_dofs_local],depth[wet_dofs_local],
IndexError: index 21525 is out of bounds for axis 0 with size 21525
Traceback (most recent call last):
  File "/home1/04637/mdl2665/WAVEx/main.py", line 259, in <module>
Traceback (most recent call last):
  File "/home1/04637/mdl2665/WAVEx/main.py", line 259, in <module>
    c,dry_dofs_local,cph,k = CFx.wave.compute_wave_speeds(x,y,sigma,theta,depth_func,u_func,v_func,N_dof_2)
  File "/home1/04637/mdl2665/WAVEx/CFx/wave.py", line 213, in compute_wave_speeds
    c_out[wet_dofs_local,:],cph[wet_dofs_local],k[wet_dofs_local] = compute_wave_speeds_pointwise(x[wet_dofs_local],y[wet_dofs_local],sigma[wet_dofs_local],theta[wet_dofs_local],depth[wet_dofs_local],
IndexError: index 24600 is out of bounds for axis 0 with size 24600
Traceback (most recent call last):
  File "/home1/04637/mdl2665/WAVEx/main.py", line 259, in <module>
Traceback (most recent call last):
  File "/home1/04637/mdl2665/WAVEx/main.py", line 259, in <module>
    c,dry_dofs_local,cph,k = CFx.wave.compute_wave_speeds(x,y,sigma,theta,depth_func,u_func,v_func,N_dof_2)
  File "/home1/04637/mdl2665/WAVEx/CFx/wave.py", line 213, in compute_wave_speeds
    c_out[wet_dofs_local,:],cph[wet_dofs_local],k[wet_dofs_local] = compute_wave_speeds_pointwise(x[wet_dofs_local],y[wet_dofs_local],sigma[wet_dofs_local],theta[wet_dofs_local],depth[wet_dofs_local],
IndexError: index 25625 is out of bounds for axis 0 with size 25625
    c,dry_dofs_local,cph,k = CFx.wave.compute_wave_speeds(x,y,sigma,theta,depth_func,u_func,v_func,N_dof_2)
  File "/home1/04637/mdl2665/WAVEx/CFx/wave.py", line 213, in compute_wave_speeds
Traceback (most recent call last):
  File "/home1/04637/mdl2665/WAVEx/main.py", line 259, in <module>
Traceback (most recent call last):
  File "/home1/04637/mdl2665/WAVEx/main.py", line 259, in <module>
Traceback (most recent call last):
  File "/home1/04637/mdl2665/WAVEx/main.py", line 259, in <module>
    c_out[wet_dofs_local,:],cph[wet_dofs_local],k[wet_dofs_local] = compute_wave_speeds_pointwise(x[wet_dofs_local],y[wet_dofs_local],sigma[wet_dofs_local],theta[wet_dofs_local],depth[wet_dofs_local],
IndexError: index 25625 is out of bounds for axis 0 with size 25625
    c,dry_dofs_local,cph,k = CFx.wave.compute_wave_speeds(x,y,sigma,theta,depth_func,u_func,v_func,N_dof_2)
  File "/home1/04637/mdl2665/WAVEx/CFx/wave.py", line 213, in compute_wave_speeds
Traceback (most recent call last):
  File "/home1/04637/mdl2665/WAVEx/main.py", line 259, in <module>
    c,dry_dofs_local,cph,k = CFx.wave.compute_wave_speeds(x,y,sigma,theta,depth_func,u_func,v_func,N_dof_2)
  File "/home1/04637/mdl2665/WAVEx/CFx/wave.py", line 213, in compute_wave_speeds
    c_out[wet_dofs_local,:],cph[wet_dofs_local],k[wet_dofs_local] = compute_wave_speeds_pointwise(x[wet_dofs_local],y[wet_dofs_local],sigma[wet_dofs_local],theta[wet_dofs_local],depth[wet_dofs_local],
IndexError: index 22550 is out of bounds for axis 0 with size 22550
Traceback (most recent call last):
  File "/home1/04637/mdl2665/WAVEx/main.py", line 259, in <module>
    c_out[wet_dofs_local,:],cph[wet_dofs_local],k[wet_dofs_local] = compute_wave_speeds_pointwise(x[wet_dofs_local],y[wet_dofs_local],sigma[wet_dofs_local],theta[wet_dofs_local],depth[wet_dofs_local],
    c_out[wet_dofs_local,:],cph[wet_dofs_local],k[wet_dofs_local] = compute_wave_speeds_pointwise(x[wet_dofs_local],y[wet_dofs_local],sigma[wet_dofs_local],theta[wet_dofs_local],depth[wet_dofs_local],
IndexError: index 25625 is out of bounds for axis 0 with size 25625
Traceback (most recent call last):
  File "/home1/04637/mdl2665/WAVEx/main.py", line 259, in <module>
    c,dry_dofs_local,cph,k = CFx.wave.compute_wave_speeds(x,y,sigma,theta,depth_func,u_func,v_func,N_dof_2)
  File "/home1/04637/mdl2665/WAVEx/CFx/wave.py", line 213, in compute_wave_speeds
IndexError: index 24600 is out of bounds for axis 0 with size 24600
    c,dry_dofs_local,cph,k = CFx.wave.compute_wave_speeds(x,y,sigma,theta,depth_func,u_func,v_func,N_dof_2)
  File "/home1/04637/mdl2665/WAVEx/CFx/wave.py", line 213, in compute_wave_speeds
    c_out[wet_dofs_local,:],cph[wet_dofs_local],k[wet_dofs_local] = compute_wave_speeds_pointwise(x[wet_dofs_local],y[wet_dofs_local],sigma[wet_dofs_local],theta[wet_dofs_local],depth[wet_dofs_local],
IndexError: index 24600 is out of bounds for axis 0 with size 24600
Traceback (most recent call last):
  File "/home1/04637/mdl2665/WAVEx/main.py", line 259, in <module>
    c,dry_dofs_local,cph,k = CFx.wave.compute_wave_speeds(x,y,sigma,theta,depth_func,u_func,v_func,N_dof_2)
  File "/home1/04637/mdl2665/WAVEx/CFx/wave.py", line 213, in compute_wave_speeds
    c_out[wet_dofs_local,:],cph[wet_dofs_local],k[wet_dofs_local] = compute_wave_speeds_pointwise(x[wet_dofs_local],y[wet_dofs_local],sigma[wet_dofs_local],theta[wet_dofs_local],depth[wet_dofs_local],
IndexError: index 25625 is out of bounds for axis 0 with size 25625
    c_out[wet_dofs_local,:],cph[wet_dofs_local],k[wet_dofs_local] = compute_wave_speeds_pointwise(x[wet_dofs_local],y[wet_dofs_local],sigma[wet_dofs_local],theta[wet_dofs_local],depth[wet_dofs_local],
    c,dry_dofs_local,cph,k = CFx.wave.compute_wave_speeds(x,y,sigma,theta,depth_func,u_func,v_func,N_dof_2)
  File "/home1/04637/mdl2665/WAVEx/CFx/wave.py", line 213, in compute_wave_speeds
IndexError: index 28700 is out of bounds for axis 0 with size 27675
    c,dry_dofs_local,cph,k = CFx.wave.compute_wave_speeds(x,y,sigma,theta,depth_func,u_func,v_func,N_dof_2)
  File "/home1/04637/mdl2665/WAVEx/CFx/wave.py", line 213, in compute_wave_speeds
Traceback (most recent call last):
  File "/home1/04637/mdl2665/WAVEx/main.py", line 259, in <module>
    c,dry_dofs_local,cph,k = CFx.wave.compute_wave_speeds(x,y,sigma,theta,depth_func,u_func,v_func,N_dof_2)
  File "/home1/04637/mdl2665/WAVEx/CFx/wave.py", line 213, in compute_wave_speeds
    c_out[wet_dofs_local,:],cph[wet_dofs_local],k[wet_dofs_local] = compute_wave_speeds_pointwise(x[wet_dofs_local],y[wet_dofs_local],sigma[wet_dofs_local],theta[wet_dofs_local],depth[wet_dofs_local],
IndexError: index 29725 is out of bounds for axis 0 with size 29725
    c_out[wet_dofs_local,:],cph[wet_dofs_local],k[wet_dofs_local] = compute_wave_speeds_pointwise(x[wet_dofs_local],y[wet_dofs_local],sigma[wet_dofs_local],theta[wet_dofs_local],depth[wet_dofs_local],
IndexError: index 24600 is out of bounds for axis 0 with size 24600
    c_out[wet_dofs_local,:],cph[wet_dofs_local],k[wet_dofs_local] = compute_wave_speeds_pointwise(x[wet_dofs_local],y[wet_dofs_local],sigma[wet_dofs_local],theta[wet_dofs_local],depth[wet_dofs_local],
IndexError: index 23575 is out of bounds for axis 0 with size 23575
    c,dry_dofs_local,cph,k = CFx.wave.compute_wave_speeds(x,y,sigma,theta,depth_func,u_func,v_func,N_dof_2)
  File "/home1/04637/mdl2665/WAVEx/CFx/wave.py", line 213, in compute_wave_speeds
Traceback (most recent call last):
  File "/home1/04637/mdl2665/WAVEx/main.py", line 259, in <module>
    c,dry_dofs_local,cph,k = CFx.wave.compute_wave_speeds(x,y,sigma,theta,depth_func,u_func,v_func,N_dof_2)
  File "/home1/04637/mdl2665/WAVEx/CFx/wave.py", line 213, in compute_wave_speeds
    c_out[wet_dofs_local,:],cph[wet_dofs_local],k[wet_dofs_local] = compute_wave_speeds_pointwise(x[wet_dofs_local],y[wet_dofs_local],sigma[wet_dofs_local],theta[wet_dofs_local],depth[wet_dofs_local],
IndexError: index 24600 is out of bounds for axis 0 with size 23575
    c_out[wet_dofs_local,:],cph[wet_dofs_local],k[wet_dofs_local] = compute_wave_speeds_pointwise(x[wet_dofs_local],y[wet_dofs_local],sigma[wet_dofs_local],theta[wet_dofs_local],depth[wet_dofs_local],
Traceback (most recent call last):
  File "/home1/04637/mdl2665/WAVEx/main.py", line 259, in <module>
    c,dry_dofs_local,cph,k = CFx.wave.compute_wave_speeds(x,y,sigma,theta,depth_func,u_func,v_func,N_dof_2)
  File "/home1/04637/mdl2665/WAVEx/CFx/wave.py", line 213, in compute_wave_speeds
    c_out[wet_dofs_local,:],cph[wet_dofs_local],k[wet_dofs_local] = compute_wave_speeds_pointwise(x[wet_dofs_local],y[wet_dofs_local],sigma[wet_dofs_local],theta[wet_dofs_local],depth[wet_dofs_local],
IndexError: index 23575 is out of bounds for axis 0 with size 23575
IndexError: index 24600 is out of bounds for axis 0 with size 24600
Traceback (most recent call last):
  File "/home1/04637/mdl2665/WAVEx/main.py", line 259, in <module>
    c,dry_dofs_local,cph,k = CFx.wave.compute_wave_speeds(x,y,sigma,theta,depth_func,u_func,v_func,N_dof_2)
  File "/home1/04637/mdl2665/WAVEx/CFx/wave.py", line 213, in compute_wave_speeds
    c_out[wet_dofs_local,:],cph[wet_dofs_local],k[wet_dofs_local] = compute_wave_speeds_pointwise(x[wet_dofs_local],y[wet_dofs_local],sigma[wet_dofs_local],theta[wet_dofs_local],depth[wet_dofs_local],
IndexError: index 22550 is out of bounds for axis 0 with size 22550
Traceback (most recent call last):
  File "/home1/04637/mdl2665/WAVEx/main.py", line 259, in <module>
    c,dry_dofs_local,cph,k = CFx.wave.compute_wave_speeds(x,y,sigma,theta,depth_func,u_func,v_func,N_dof_2)
  File "/home1/04637/mdl2665/WAVEx/CFx/wave.py", line 213, in compute_wave_speeds
    c_out[wet_dofs_local,:],cph[wet_dofs_local],k[wet_dofs_local] = compute_wave_speeds_pointwise(x[wet_dofs_local],y[wet_dofs_local],sigma[wet_dofs_local],theta[wet_dofs_local],depth[wet_dofs_local],
IndexError: index 23575 is out of bounds for axis 0 with size 23575
Traceback (most recent call last):
  File "/home1/04637/mdl2665/WAVEx/main.py", line 259, in <module>
    c,dry_dofs_local,cph,k = CFx.wave.compute_wave_speeds(x,y,sigma,theta,depth_func,u_func,v_func,N_dof_2)
  File "/home1/04637/mdl2665/WAVEx/CFx/wave.py", line 213, in compute_wave_speeds
    c_out[wet_dofs_local,:],cph[wet_dofs_local],k[wet_dofs_local] = compute_wave_speeds_pointwise(x[wet_dofs_local],y[wet_dofs_local],sigma[wet_dofs_local],theta[wet_dofs_local],depth[wet_dofs_local],
IndexError: index 23575 is out of bounds for axis 0 with size 23575
Traceback (most recent call last):
  File "/home1/04637/mdl2665/WAVEx/main.py", line 259, in <module>
    c,dry_dofs_local,cph,k = CFx.wave.compute_wave_speeds(x,y,sigma,theta,depth_func,u_func,v_func,N_dof_2)
  File "/home1/04637/mdl2665/WAVEx/CFx/wave.py", line 213, in compute_wave_speeds
    c_out[wet_dofs_local,:],cph[wet_dofs_local],k[wet_dofs_local] = compute_wave_speeds_pointwise(x[wet_dofs_local],y[wet_dofs_local],sigma[wet_dofs_local],theta[wet_dofs_local],depth[wet_dofs_local],
IndexError: index 24600 is out of bounds for axis 0 with size 24600
Traceback (most recent call last):
  File "/home1/04637/mdl2665/WAVEx/main.py", line 259, in <module>
    c,dry_dofs_local,cph,k = CFx.wave.compute_wave_speeds(x,y,sigma,theta,depth_func,u_func,v_func,N_dof_2)
  File "/home1/04637/mdl2665/WAVEx/CFx/wave.py", line 213, in compute_wave_speeds
    c_out[wet_dofs_local,:],cph[wet_dofs_local],k[wet_dofs_local] = compute_wave_speeds_pointwise(x[wet_dofs_local],y[wet_dofs_local],sigma[wet_dofs_local],theta[wet_dofs_local],depth[wet_dofs_local],
IndexError: index 22550 is out of bounds for axis 0 with size 22550
Traceback (most recent call last):
  File "/home1/04637/mdl2665/WAVEx/main.py", line 259, in <module>
    c,dry_dofs_local,cph,k = CFx.wave.compute_wave_speeds(x,y,sigma,theta,depth_func,u_func,v_func,N_dof_2)
  File "/home1/04637/mdl2665/WAVEx/CFx/wave.py", line 213, in compute_wave_speeds
    c_out[wet_dofs_local,:],cph[wet_dofs_local],k[wet_dofs_local] = compute_wave_speeds_pointwise(x[wet_dofs_local],y[wet_dofs_local],sigma[wet_dofs_local],theta[wet_dofs_local],depth[wet_dofs_local],
IndexError: index 25625 is out of bounds for axis 0 with size 25625
    c_out[wet_dofs_local,:],cph[wet_dofs_local],k[wet_dofs_local] = compute_wave_speeds_pointwise(x[wet_dofs_local],y[wet_dofs_local],sigma[wet_dofs_local],theta[wet_dofs_local],depth[wet_dofs_local],
IndexError: index 26650 is out of bounds for axis 0 with size 26650
Traceback (most recent call last):
  File "/home1/04637/mdl2665/WAVEx/main.py", line 259, in <module>
    c,dry_dofs_local,cph,k = CFx.wave.compute_wave_speeds(x,y,sigma,theta,depth_func,u_func,v_func,N_dof_2)
  File "/home1/04637/mdl2665/WAVEx/CFx/wave.py", line 213, in compute_wave_speeds
    c_out[wet_dofs_local,:],cph[wet_dofs_local],k[wet_dofs_local] = compute_wave_speeds_pointwise(x[wet_dofs_local],y[wet_dofs_local],sigma[wet_dofs_local],theta[wet_dofs_local],depth[wet_dofs_local],
IndexError: index 27675 is out of bounds for axis 0 with size 27675
Traceback (most recent call last):
  File "/home1/04637/mdl2665/WAVEx/main.py", line 259, in <module>
    c,dry_dofs_local,cph,k = CFx.wave.compute_wave_speeds(x,y,sigma,theta,depth_func,u_func,v_func,N_dof_2)
  File "/home1/04637/mdl2665/WAVEx/CFx/wave.py", line 213, in compute_wave_speeds
    c_out[wet_dofs_local,:],cph[wet_dofs_local],k[wet_dofs_local] = compute_wave_speeds_pointwise(x[wet_dofs_local],y[wet_dofs_local],sigma[wet_dofs_local],theta[wet_dofs_local],depth[wet_dofs_local],
IndexError: index 27675 is out of bounds for axis 0 with size 27675
Traceback (most recent call last):
  File "/home1/04637/mdl2665/WAVEx/main.py", line 259, in <module>
    c,dry_dofs_local,cph,k = CFx.wave.compute_wave_speeds(x,y,sigma,theta,depth_func,u_func,v_func,N_dof_2)
  File "/home1/04637/mdl2665/WAVEx/CFx/wave.py", line 213, in compute_wave_speeds
    c_out[wet_dofs_local,:],cph[wet_dofs_local],k[wet_dofs_local] = compute_wave_speeds_pointwise(x[wet_dofs_local],y[wet_dofs_local],sigma[wet_dofs_local],theta[wet_dofs_local],depth[wet_dofs_local],
IndexError: index 24600 is out of bounds for axis 0 with size 24600
    c,dry_dofs_local,cph,k = CFx.wave.compute_wave_speeds(x,y,sigma,theta,depth_func,u_func,v_func,N_dof_2)
  File "/home1/04637/mdl2665/WAVEx/CFx/wave.py", line 213, in compute_wave_speeds
Traceback (most recent call last):
  File "/home1/04637/mdl2665/WAVEx/main.py", line 259, in <module>
    c,dry_dofs_local,cph,k = CFx.wave.compute_wave_speeds(x,y,sigma,theta,depth_func,u_func,v_func,N_dof_2)
  File "/home1/04637/mdl2665/WAVEx/CFx/wave.py", line 213, in compute_wave_speeds
    c_out[wet_dofs_local,:],cph[wet_dofs_local],k[wet_dofs_local] = compute_wave_speeds_pointwise(x[wet_dofs_local],y[wet_dofs_local],sigma[wet_dofs_local],theta[wet_dofs_local],depth[wet_dofs_local],
IndexError: index 27675 is out of bounds for axis 0 with size 27675
Traceback (most recent call last):
  File "/home1/04637/mdl2665/WAVEx/main.py", line 259, in <module>
    c,dry_dofs_local,cph,k = CFx.wave.compute_wave_speeds(x,y,sigma,theta,depth_func,u_func,v_func,N_dof_2)
  File "/home1/04637/mdl2665/WAVEx/CFx/wave.py", line 213, in compute_wave_speeds
    c_out[wet_dofs_local,:],cph[wet_dofs_local],k[wet_dofs_local] = compute_wave_speeds_pointwise(x[wet_dofs_local],y[wet_dofs_local],sigma[wet_dofs_local],theta[wet_dofs_local],depth[wet_dofs_local],
IndexError: index 26650 is out of bounds for axis 0 with size 26650
Traceback (most recent call last):
  File "/home1/04637/mdl2665/WAVEx/main.py", line 259, in <module>
Traceback (most recent call last):
  File "/home1/04637/mdl2665/WAVEx/main.py", line 259, in <module>
    c,dry_dofs_local,cph,k = CFx.wave.compute_wave_speeds(x,y,sigma,theta,depth_func,u_func,v_func,N_dof_2)
  File "/home1/04637/mdl2665/WAVEx/CFx/wave.py", line 213, in compute_wave_speeds
    c_out[wet_dofs_local,:],cph[wet_dofs_local],k[wet_dofs_local] = compute_wave_speeds_pointwise(x[wet_dofs_local],y[wet_dofs_local],sigma[wet_dofs_local],theta[wet_dofs_local],depth[wet_dofs_local],
IndexError: index 24600 is out of bounds for axis 0 with size 24600
Traceback (most recent call last):
  File "/home1/04637/mdl2665/WAVEx/main.py", line 259, in <module>
    c,dry_dofs_local,cph,k = CFx.wave.compute_wave_speeds(x,y,sigma,theta,depth_func,u_func,v_func,N_dof_2)
  File "/home1/04637/mdl2665/WAVEx/CFx/wave.py", line 213, in compute_wave_speeds
    c_out[wet_dofs_local,:],cph[wet_dofs_local],k[wet_dofs_local] = compute_wave_speeds_pointwise(x[wet_dofs_local],y[wet_dofs_local],sigma[wet_dofs_local],theta[wet_dofs_local],depth[wet_dofs_local],
IndexError: index 24600 is out of bounds for axis 0 with size 24600
Traceback (most recent call last):
  File "/home1/04637/mdl2665/WAVEx/main.py", line 259, in <module>
Traceback (most recent call last):
  File "/home1/04637/mdl2665/WAVEx/main.py", line 259, in <module>
    c,dry_dofs_local,cph,k = CFx.wave.compute_wave_speeds(x,y,sigma,theta,depth_func,u_func,v_func,N_dof_2)
  File "/home1/04637/mdl2665/WAVEx/CFx/wave.py", line 213, in compute_wave_speeds
    c,dry_dofs_local,cph,k = CFx.wave.compute_wave_speeds(x,y,sigma,theta,depth_func,u_func,v_func,N_dof_2)
  File "/home1/04637/mdl2665/WAVEx/CFx/wave.py", line 213, in compute_wave_speeds
    c_out[wet_dofs_local,:],cph[wet_dofs_local],k[wet_dofs_local] = compute_wave_speeds_pointwise(x[wet_dofs_local],y[wet_dofs_local],sigma[wet_dofs_local],theta[wet_dofs_local],depth[wet_dofs_local],
IndexError: index 25625 is out of bounds for axis 0 with size 25625
Traceback (most recent call last):
  File "/home1/04637/mdl2665/WAVEx/main.py", line 259, in <module>
    c,dry_dofs_local,cph,k = CFx.wave.compute_wave_speeds(x,y,sigma,theta,depth_func,u_func,v_func,N_dof_2)
  File "/home1/04637/mdl2665/WAVEx/CFx/wave.py", line 213, in compute_wave_speeds
    c_out[wet_dofs_local,:],cph[wet_dofs_local],k[wet_dofs_local] = compute_wave_speeds_pointwise(x[wet_dofs_local],y[wet_dofs_local],sigma[wet_dofs_local],theta[wet_dofs_local],depth[wet_dofs_local],
IndexError: index 23575 is out of bounds for axis 0 with size 23575
Traceback (most recent call last):
  File "/home1/04637/mdl2665/WAVEx/main.py", line 259, in <module>
    c,dry_dofs_local,cph,k = CFx.wave.compute_wave_speeds(x,y,sigma,theta,depth_func,u_func,v_func,N_dof_2)
  File "/home1/04637/mdl2665/WAVEx/CFx/wave.py", line 213, in compute_wave_speeds
    c_out[wet_dofs_local,:],cph[wet_dofs_local],k[wet_dofs_local] = compute_wave_speeds_pointwise(x[wet_dofs_local],y[wet_dofs_local],sigma[wet_dofs_local],theta[wet_dofs_local],depth[wet_dofs_local],
IndexError: index 23575 is out of bounds for axis 0 with size 23575
Traceback (most recent call last):
  File "/home1/04637/mdl2665/WAVEx/main.py", line 259, in <module>
    c,dry_dofs_local,cph,k = CFx.wave.compute_wave_speeds(x,y,sigma,theta,depth_func,u_func,v_func,N_dof_2)
  File "/home1/04637/mdl2665/WAVEx/CFx/wave.py", line 213, in compute_wave_speeds
    c_out[wet_dofs_local,:],cph[wet_dofs_local],k[wet_dofs_local] = compute_wave_speeds_pointwise(x[wet_dofs_local],y[wet_dofs_local],sigma[wet_dofs_local],theta[wet_dofs_local],depth[wet_dofs_local],
IndexError: index 28700 is out of bounds for axis 0 with size 27675
    c,dry_dofs_local,cph,k = CFx.wave.compute_wave_speeds(x,y,sigma,theta,depth_func,u_func,v_func,N_dof_2)
  File "/home1/04637/mdl2665/WAVEx/CFx/wave.py", line 213, in compute_wave_speeds
    c_out[wet_dofs_local,:],cph[wet_dofs_local],k[wet_dofs_local] = compute_wave_speeds_pointwise(x[wet_dofs_local],y[wet_dofs_local],sigma[wet_dofs_local],theta[wet_dofs_local],depth[wet_dofs_local],
IndexError: index 23575 is out of bounds for axis 0 with size 23575
    c_out[wet_dofs_local,:],cph[wet_dofs_local],k[wet_dofs_local] = compute_wave_speeds_pointwise(x[wet_dofs_local],y[wet_dofs_local],sigma[wet_dofs_local],theta[wet_dofs_local],depth[wet_dofs_local],
IndexError: index 24600 is out of bounds for axis 0 with size 24600
    c_out[wet_dofs_local,:],cph[wet_dofs_local],k[wet_dofs_local] = compute_wave_speeds_pointwise(x[wet_dofs_local],y[wet_dofs_local],sigma[wet_dofs_local],theta[wet_dofs_local],depth[wet_dofs_local],
IndexError: index 25625 is out of bounds for axis 0 with size 25625
Traceback (most recent call last):
  File "/home1/04637/mdl2665/WAVEx/main.py", line 259, in <module>
    c,dry_dofs_local,cph,k = CFx.wave.compute_wave_speeds(x,y,sigma,theta,depth_func,u_func,v_func,N_dof_2)
  File "/home1/04637/mdl2665/WAVEx/CFx/wave.py", line 213, in compute_wave_speeds
    c_out[wet_dofs_local,:],cph[wet_dofs_local],k[wet_dofs_local] = compute_wave_speeds_pointwise(x[wet_dofs_local],y[wet_dofs_local],sigma[wet_dofs_local],theta[wet_dofs_local],depth[wet_dofs_local],
    c,dry_dofs_local,cph,k = CFx.wave.compute_wave_speeds(x,y,sigma,theta,depth_func,u_func,v_func,N_dof_2)
  File "/home1/04637/mdl2665/WAVEx/CFx/wave.py", line 213, in compute_wave_speeds
Traceback (most recent call last):
  File "/home1/04637/mdl2665/WAVEx/main.py", line 259, in <module>
IndexError: index 25625 is out of bounds for axis 0 with size 25625
    c,dry_dofs_local,cph,k = CFx.wave.compute_wave_speeds(x,y,sigma,theta,depth_func,u_func,v_func,N_dof_2)
  File "/home1/04637/mdl2665/WAVEx/CFx/wave.py", line 213, in compute_wave_speeds
    c_out[wet_dofs_local,:],cph[wet_dofs_local],k[wet_dofs_local] = compute_wave_speeds_pointwise(x[wet_dofs_local],y[wet_dofs_local],sigma[wet_dofs_local],theta[wet_dofs_local],depth[wet_dofs_local],
IndexError: index 22550 is out of bounds for axis 0 with size 22550
Traceback (most recent call last):
  File "/home1/04637/mdl2665/WAVEx/main.py", line 259, in <module>
    c,dry_dofs_local,cph,k = CFx.wave.compute_wave_speeds(x,y,sigma,theta,depth_func,u_func,v_func,N_dof_2)
  File "/home1/04637/mdl2665/WAVEx/CFx/wave.py", line 213, in compute_wave_speeds
Traceback (most recent call last):
  File "/home1/04637/mdl2665/WAVEx/main.py", line 259, in <module>
    c_out[wet_dofs_local,:],cph[wet_dofs_local],k[wet_dofs_local] = compute_wave_speeds_pointwise(x[wet_dofs_local],y[wet_dofs_local],sigma[wet_dofs_local],theta[wet_dofs_local],depth[wet_dofs_local],
IndexError: index 29725 is out of bounds for axis 0 with size 29725
Traceback (most recent call last):
  File "/home1/04637/mdl2665/WAVEx/main.py", line 259, in <module>
Traceback (most recent call last):
  File "/home1/04637/mdl2665/WAVEx/main.py", line 259, in <module>
    c,dry_dofs_local,cph,k = CFx.wave.compute_wave_speeds(x,y,sigma,theta,depth_func,u_func,v_func,N_dof_2)
  File "/home1/04637/mdl2665/WAVEx/CFx/wave.py", line 213, in compute_wave_speeds
    c_out[wet_dofs_local,:],cph[wet_dofs_local],k[wet_dofs_local] = compute_wave_speeds_pointwise(x[wet_dofs_local],y[wet_dofs_local],sigma[wet_dofs_local],theta[wet_dofs_local],depth[wet_dofs_local],
IndexError: index 26650 is out of bounds for axis 0 with size 26650
    c,dry_dofs_local,cph,k = CFx.wave.compute_wave_speeds(x,y,sigma,theta,depth_func,u_func,v_func,N_dof_2)
  File "/home1/04637/mdl2665/WAVEx/CFx/wave.py", line 213, in compute_wave_speeds
    c_out[wet_dofs_local,:],cph[wet_dofs_local],k[wet_dofs_local] = compute_wave_speeds_pointwise(x[wet_dofs_local],y[wet_dofs_local],sigma[wet_dofs_local],theta[wet_dofs_local],depth[wet_dofs_local],
IndexError: index 25625 is out of bounds for axis 0 with size 25625
    c,dry_dofs_local,cph,k = CFx.wave.compute_wave_speeds(x,y,sigma,theta,depth_func,u_func,v_func,N_dof_2)
  File "/home1/04637/mdl2665/WAVEx/CFx/wave.py", line 213, in compute_wave_speeds
    c_out[wet_dofs_local,:],cph[wet_dofs_local],k[wet_dofs_local] = compute_wave_speeds_pointwise(x[wet_dofs_local],y[wet_dofs_local],sigma[wet_dofs_local],theta[wet_dofs_local],depth[wet_dofs_local],
IndexError: index 23575 is out of bounds for axis 0 with size 23575
Traceback (most recent call last):
  File "/home1/04637/mdl2665/WAVEx/main.py", line 259, in <module>
    c,dry_dofs_local,cph,k = CFx.wave.compute_wave_speeds(x,y,sigma,theta,depth_func,u_func,v_func,N_dof_2)
  File "/home1/04637/mdl2665/WAVEx/CFx/wave.py", line 213, in compute_wave_speeds
    c_out[wet_dofs_local,:],cph[wet_dofs_local],k[wet_dofs_local] = compute_wave_speeds_pointwise(x[wet_dofs_local],y[wet_dofs_local],sigma[wet_dofs_local],theta[wet_dofs_local],depth[wet_dofs_local],
IndexError: index 25625 is out of bounds for axis 0 with size 25625
Traceback (most recent call last):
  File "/home1/04637/mdl2665/WAVEx/main.py", line 259, in <module>
    c,dry_dofs_local,cph,k = CFx.wave.compute_wave_speeds(x,y,sigma,theta,depth_func,u_func,v_func,N_dof_2)
  File "/home1/04637/mdl2665/WAVEx/CFx/wave.py", line 213, in compute_wave_speeds
    c_out[wet_dofs_local,:],cph[wet_dofs_local],k[wet_dofs_local] = compute_wave_speeds_pointwise(x[wet_dofs_local],y[wet_dofs_local],sigma[wet_dofs_local],theta[wet_dofs_local],depth[wet_dofs_local],
IndexError: index 27675 is out of bounds for axis 0 with size 26650
    c,dry_dofs_local,cph,k = CFx.wave.compute_wave_speeds(x,y,sigma,theta,depth_func,u_func,v_func,N_dof_2)
  File "/home1/04637/mdl2665/WAVEx/CFx/wave.py", line 213, in compute_wave_speeds
    c_out[wet_dofs_local,:],cph[wet_dofs_local],k[wet_dofs_local] = compute_wave_speeds_pointwise(x[wet_dofs_local],y[wet_dofs_local],sigma[wet_dofs_local],theta[wet_dofs_local],depth[wet_dofs_local],
IndexError: index 25625 is out of bounds for axis 0 with size 24600
Traceback (most recent call last):
  File "/home1/04637/mdl2665/WAVEx/main.py", line 259, in <module>
    c,dry_dofs_local,cph,k = CFx.wave.compute_wave_speeds(x,y,sigma,theta,depth_func,u_func,v_func,N_dof_2)
  File "/home1/04637/mdl2665/WAVEx/CFx/wave.py", line 213, in compute_wave_speeds
    c_out[wet_dofs_local,:],cph[wet_dofs_local],k[wet_dofs_local] = compute_wave_speeds_pointwise(x[wet_dofs_local],y[wet_dofs_local],sigma[wet_dofs_local],theta[wet_dofs_local],depth[wet_dofs_local],
IndexError: index 23575 is out of bounds for axis 0 with size 23575
Traceback (most recent call last):
  File "/home1/04637/mdl2665/WAVEx/main.py", line 259, in <module>
    c,dry_dofs_local,cph,k = CFx.wave.compute_wave_speeds(x,y,sigma,theta,depth_func,u_func,v_func,N_dof_2)
  File "/home1/04637/mdl2665/WAVEx/CFx/wave.py", line 213, in compute_wave_speeds
    c_out[wet_dofs_local,:],cph[wet_dofs_local],k[wet_dofs_local] = compute_wave_speeds_pointwise(x[wet_dofs_local],y[wet_dofs_local],sigma[wet_dofs_local],theta[wet_dofs_local],depth[wet_dofs_local],
IndexError: index 25625 is out of bounds for axis 0 with size 25625
Traceback (most recent call last):
  File "/home1/04637/mdl2665/WAVEx/main.py", line 259, in <module>
    c,dry_dofs_local,cph,k = CFx.wave.compute_wave_speeds(x,y,sigma,theta,depth_func,u_func,v_func,N_dof_2)
  File "/home1/04637/mdl2665/WAVEx/CFx/wave.py", line 213, in compute_wave_speeds
    c_out[wet_dofs_local,:],cph[wet_dofs_local],k[wet_dofs_local] = compute_wave_speeds_pointwise(x[wet_dofs_local],y[wet_dofs_local],sigma[wet_dofs_local],theta[wet_dofs_local],depth[wet_dofs_local],
IndexError: index 26650 is out of bounds for axis 0 with size 26650
Traceback (most recent call last):
  File "/home1/04637/mdl2665/WAVEx/main.py", line 259, in <module>
    c,dry_dofs_local,cph,k = CFx.wave.compute_wave_speeds(x,y,sigma,theta,depth_func,u_func,v_func,N_dof_2)
  File "/home1/04637/mdl2665/WAVEx/CFx/wave.py", line 213, in compute_wave_speeds
    c_out[wet_dofs_local,:],cph[wet_dofs_local],k[wet_dofs_local] = compute_wave_speeds_pointwise(x[wet_dofs_local],y[wet_dofs_local],sigma[wet_dofs_local],theta[wet_dofs_local],depth[wet_dofs_local],
IndexError: index 29725 is out of bounds for axis 0 with size 28700
Traceback (most recent call last):
  File "/home1/04637/mdl2665/WAVEx/main.py", line 259, in <module>
    c,dry_dofs_local,cph,k = CFx.wave.compute_wave_speeds(x,y,sigma,theta,depth_func,u_func,v_func,N_dof_2)
  File "/home1/04637/mdl2665/WAVEx/CFx/wave.py", line 213, in compute_wave_speeds
    c_out[wet_dofs_local,:],cph[wet_dofs_local],k[wet_dofs_local] = compute_wave_speeds_pointwise(x[wet_dofs_local],y[wet_dofs_local],sigma[wet_dofs_local],theta[wet_dofs_local],depth[wet_dofs_local],
IndexError: index 26650 is out of bounds for axis 0 with size 26650
Traceback (most recent call last):
  File "/home1/04637/mdl2665/WAVEx/main.py", line 259, in <module>
    c,dry_dofs_local,cph,k = CFx.wave.compute_wave_speeds(x,y,sigma,theta,depth_func,u_func,v_func,N_dof_2)
  File "/home1/04637/mdl2665/WAVEx/CFx/wave.py", line 213, in compute_wave_speeds
    c_out[wet_dofs_local,:],cph[wet_dofs_local],k[wet_dofs_local] = compute_wave_speeds_pointwise(x[wet_dofs_local],y[wet_dofs_local],sigma[wet_dofs_local],theta[wet_dofs_local],depth[wet_dofs_local],
IndexError: index 26650 is out of bounds for axis 0 with size 26650
Traceback (most recent call last):
  File "/home1/04637/mdl2665/WAVEx/main.py", line 259, in <module>
    c,dry_dofs_local,cph,k = CFx.wave.compute_wave_speeds(x,y,sigma,theta,depth_func,u_func,v_func,N_dof_2)
  File "/home1/04637/mdl2665/WAVEx/CFx/wave.py", line 213, in compute_wave_speeds
    c_out[wet_dofs_local,:],cph[wet_dofs_local],k[wet_dofs_local] = compute_wave_speeds_pointwise(x[wet_dofs_local],y[wet_dofs_local],sigma[wet_dofs_local],theta[wet_dofs_local],depth[wet_dofs_local],
IndexError: index 23575 is out of bounds for axis 0 with size 23575
    c,dry_dofs_local,cph,k = CFx.wave.compute_wave_speeds(x,y,sigma,theta,depth_func,u_func,v_func,N_dof_2)
  File "/home1/04637/mdl2665/WAVEx/CFx/wave.py", line 213, in compute_wave_speeds
    c_out[wet_dofs_local,:],cph[wet_dofs_local],k[wet_dofs_local] = compute_wave_speeds_pointwise(x[wet_dofs_local],y[wet_dofs_local],sigma[wet_dofs_local],theta[wet_dofs_local],depth[wet_dofs_local],
IndexError: index 25625 is out of bounds for axis 0 with size 25625
Traceback (most recent call last):
  File "/home1/04637/mdl2665/WAVEx/main.py", line 259, in <module>
    c,dry_dofs_local,cph,k = CFx.wave.compute_wave_speeds(x,y,sigma,theta,depth_func,u_func,v_func,N_dof_2)
  File "/home1/04637/mdl2665/WAVEx/CFx/wave.py", line 213, in compute_wave_speeds
    c_out[wet_dofs_local,:],cph[wet_dofs_local],k[wet_dofs_local] = compute_wave_speeds_pointwise(x[wet_dofs_local],y[wet_dofs_local],sigma[wet_dofs_local],theta[wet_dofs_local],depth[wet_dofs_local],
IndexError: index 26650 is out of bounds for axis 0 with size 25625
    c_out[wet_dofs_local,:],cph[wet_dofs_local],k[wet_dofs_local] = compute_wave_speeds_pointwise(x[wet_dofs_local],y[wet_dofs_local],sigma[wet_dofs_local],theta[wet_dofs_local],depth[wet_dofs_local],
IndexError: index 26650 is out of bounds for axis 0 with size 26650
Traceback (most recent call last):
  File "/home1/04637/mdl2665/WAVEx/main.py", line 259, in <module>
    c,dry_dofs_local,cph,k = CFx.wave.compute_wave_speeds(x,y,sigma,theta,depth_func,u_func,v_func,N_dof_2)
  File "/home1/04637/mdl2665/WAVEx/CFx/wave.py", line 213, in compute_wave_speeds
    c_out[wet_dofs_local,:],cph[wet_dofs_local],k[wet_dofs_local] = compute_wave_speeds_pointwise(x[wet_dofs_local],y[wet_dofs_local],sigma[wet_dofs_local],theta[wet_dofs_local],depth[wet_dofs_local],
IndexError: index 24600 is out of bounds for axis 0 with size 23575
Traceback (most recent call last):
  File "/home1/04637/mdl2665/WAVEx/main.py", line 259, in <module>
    c,dry_dofs_local,cph,k = CFx.wave.compute_wave_speeds(x,y,sigma,theta,depth_func,u_func,v_func,N_dof_2)
  File "/home1/04637/mdl2665/WAVEx/CFx/wave.py", line 213, in compute_wave_speeds
    c_out[wet_dofs_local,:],cph[wet_dofs_local],k[wet_dofs_local] = compute_wave_speeds_pointwise(x[wet_dofs_local],y[wet_dofs_local],sigma[wet_dofs_local],theta[wet_dofs_local],depth[wet_dofs_local],
IndexError: index 26650 is out of bounds for axis 0 with size 26650
Traceback (most recent call last):
  File "/home1/04637/mdl2665/WAVEx/main.py", line 259, in <module>
    c,dry_dofs_local,cph,k = CFx.wave.compute_wave_speeds(x,y,sigma,theta,depth_func,u_func,v_func,N_dof_2)
  File "/home1/04637/mdl2665/WAVEx/CFx/wave.py", line 213, in compute_wave_speeds
Traceback (most recent call last):
  File "/home1/04637/mdl2665/WAVEx/main.py", line 259, in <module>
Traceback (most recent call last):
  File "/home1/04637/mdl2665/WAVEx/main.py", line 259, in <module>
    c,dry_dofs_local,cph,k = CFx.wave.compute_wave_speeds(x,y,sigma,theta,depth_func,u_func,v_func,N_dof_2)
  File "/home1/04637/mdl2665/WAVEx/CFx/wave.py", line 213, in compute_wave_speeds
    c_out[wet_dofs_local,:],cph[wet_dofs_local],k[wet_dofs_local] = compute_wave_speeds_pointwise(x[wet_dofs_local],y[wet_dofs_local],sigma[wet_dofs_local],theta[wet_dofs_local],depth[wet_dofs_local],
IndexError: index 26650 is out of bounds for axis 0 with size 26650
    c,dry_dofs_local,cph,k = CFx.wave.compute_wave_speeds(x,y,sigma,theta,depth_func,u_func,v_func,N_dof_2)
  File "/home1/04637/mdl2665/WAVEx/CFx/wave.py", line 213, in compute_wave_speeds
    c_out[wet_dofs_local,:],cph[wet_dofs_local],k[wet_dofs_local] = compute_wave_speeds_pointwise(x[wet_dofs_local],y[wet_dofs_local],sigma[wet_dofs_local],theta[wet_dofs_local],depth[wet_dofs_local],
IndexError: index 25625 is out of bounds for axis 0 with size 25625
    c_out[wet_dofs_local,:],cph[wet_dofs_local],k[wet_dofs_local] = compute_wave_speeds_pointwise(x[wet_dofs_local],y[wet_dofs_local],sigma[wet_dofs_local],theta[wet_dofs_local],depth[wet_dofs_local],
IndexError: index 28700 is out of bounds for axis 0 with size 28700
srun: Job step aborted: Waiting up to 32 seconds for job step to finish.
srun: got SIGCONT
slurmstepd: error: *** JOB 629351 ON c306-013 CANCELLED AT 2022-12-29T12:17:57 ***
[125]PETSC ERROR: ------------------------------------------------------------------------
[125]PETSC ERROR: Caught signal number 15 Terminate: Some process (or the batch system) has told this process to end
[125]PETSC ERROR: Try option -start_in_debugger or -on_error_attach_debugger
[125]PETSC ERROR: or see https://petsc.org/release/faq/#valgrind
[125]PETSC ERROR: or try http://valgrind.org on GNU/linux and Apple MacOS to find memory corruption errors
[125]PETSC ERROR: configure using --with-debugging=yes, recompile, link, and run 
[125]PETSC ERROR: to get more information on the crash.
application called MPI_Abort(MPI_COMM_WORLD, 59) - process 125
[129]PETSC ERROR: ------------------------------------------------------------------------
[129]PETSC ERROR: Caught signal number 15 Terminate: Some process (or the batch system) has told this process to end
[129]PETSC ERROR: Try option -start_in_debugger or -on_error_attach_debugger
[129]PETSC ERROR: or see https://petsc.org/release/faq/#valgrind
[129]PETSC ERROR: or try http://valgrind.org on GNU/linux and Apple MacOS to find memory corruption errors
[129]PETSC ERROR: configure using --with-debugging=yes, recompile, link, and run 
[129]PETSC ERROR: to get more information on the crash.
application called MPI_Abort(MPI_COMM_WORLD, 59) - process 129
[132]PETSC ERROR: ------------------------------------------------------------------------
[132]PETSC ERROR: Caught signal number 15 Terminate: Some process (or the batch system) has told this process to end
[132]PETSC ERROR: Try option -start_in_debugger or -on_error_attach_debugger
[132]PETSC ERROR: or see https://petsc.org/release/faq/#valgrind
[132]PETSC ERROR: or try http://valgrind.org on GNU/linux and Apple MacOS to find memory corruption errors
[132]PETSC ERROR: configure using --with-debugging=yes, recompile, link, and run 
[132]PETSC ERROR: to get more information on the crash.
application called MPI_Abort(MPI_COMM_WORLD, 59) - process 132
[133]PETSC ERROR: ------------------------------------------------------------------------
[133]PETSC ERROR: Caught signal number 15 Terminate: Some process (or the batch system) has told this process to end
[133]PETSC ERROR: Try option -start_in_debugger or -on_error_attach_debugger
[133]PETSC ERROR: or see https://petsc.org/release/faq/#valgrind
[133]PETSC ERROR: or try http://valgrind.org on GNU/linux and Apple MacOS to find memory corruption errors
[133]PETSC ERROR: configure using --with-debugging=yes, recompile, link, and run 
[133]PETSC ERROR: to get more information on the crash.
application called MPI_Abort(MPI_COMM_WORLD, 59) - process 133
[135]PETSC ERROR: ------------------------------------------------------------------------
[135]PETSC ERROR: Caught signal number 15 Terminate: Some process (or the batch system) has told this process to end
[135]PETSC ERROR: Try option -start_in_debugger or -on_error_attach_debugger
[135]PETSC ERROR: or see https://petsc.org/release/faq/#valgrind
[135]PETSC ERROR: or try http://valgrind.org on GNU/linux and Apple MacOS to find memory corruption errors
[135]PETSC ERROR: configure using --with-debugging=yes, recompile, link, and run 
[135]PETSC ERROR: to get more information on the crash.
application called MPI_Abort(MPI_COMM_WORLD, 59) - process 135
[136]PETSC ERROR: ------------------------------------------------------------------------
[136]PETSC ERROR: Caught signal number 15 Terminate: Some process (or the batch system) has told this process to end
[136]PETSC ERROR: Try option -start_in_debugger or -on_error_attach_debugger
[136]PETSC ERROR: or see https://petsc.org/release/faq/#valgrind
[136]PETSC ERROR: or try http://valgrind.org on GNU/linux and Apple MacOS to find memory corruption errors
[136]PETSC ERROR: configure using --with-debugging=yes, recompile, link, and run 
[136]PETSC ERROR: to get more information on the crash.
application called MPI_Abort(MPI_COMM_WORLD, 59) - process 136
[137]PETSC ERROR: ------------------------------------------------------------------------
[137]PETSC ERROR: Caught signal number 15 Terminate: Some process (or the batch system) has told this process to end
[137]PETSC ERROR: Try option -start_in_debugger or -on_error_attach_debugger
[137]PETSC ERROR: or see https://petsc.org/release/faq/#valgrind
[137]PETSC ERROR: or try http://valgrind.org on GNU/linux and Apple MacOS to find memory corruption errors
[137]PETSC ERROR: configure using --with-debugging=yes, recompile, link, and run 
[137]PETSC ERROR: to get more information on the crash.
application called MPI_Abort(MPI_COMM_WORLD, 59) - process 137
[138]PETSC ERROR: ------------------------------------------------------------------------
[138]PETSC ERROR: Caught signal number 15 Terminate: Some process (or the batch system) has told this process to end
[138]PETSC ERROR: Try option -start_in_debugger or -on_error_attach_debugger
[138]PETSC ERROR: or see https://petsc.org/release/faq/#valgrind
[138]PETSC ERROR: or try http://valgrind.org on GNU/linux and Apple MacOS to find memory corruption errors
[138]PETSC ERROR: configure using --with-debugging=yes, recompile, link, and run 
[138]PETSC ERROR: to get more information on the crash.
application called MPI_Abort(MPI_COMM_WORLD, 59) - process 138
[141]PETSC ERROR: ------------------------------------------------------------------------
[141]PETSC ERROR: Caught signal number 15 Terminate: Some process (or the batch system) has told this process to end
[141]PETSC ERROR: Try option -start_in_debugger or -on_error_attach_debugger
[141]PETSC ERROR: or see https://petsc.org/release/faq/#valgrind
[141]PETSC ERROR: or try http://valgrind.org on GNU/linux and Apple MacOS to find memory corruption errors
[141]PETSC ERROR: configure using --with-debugging=yes, recompile, link, and run 
[141]PETSC ERROR: to get more information on the crash.
application called MPI_Abort(MPI_COMM_WORLD, 59) - process 141
[142]PETSC ERROR: ------------------------------------------------------------------------
[142]PETSC ERROR: Caught signal number 15 Terminate: Some process (or the batch system) has told this process to end
[142]PETSC ERROR: Try option -start_in_debugger or -on_error_attach_debugger
[142]PETSC ERROR: or see https://petsc.org/release/faq/#valgrind
[142]PETSC ERROR: or try http://valgrind.org on GNU/linux and Apple MacOS to find memory corruption errors
[142]PETSC ERROR: configure using --with-debugging=yes, recompile, link, and run 
[142]PETSC ERROR: to get more information on the crash.
application called MPI_Abort(MPI_COMM_WORLD, 59) - process 142
[145]PETSC ERROR: ------------------------------------------------------------------------
[145]PETSC ERROR: Caught signal number 15 Terminate: Some process (or the batch system) has told this process to end
[145]PETSC ERROR: Try option -start_in_debugger or -on_error_attach_debugger
[145]PETSC ERROR: or see https://petsc.org/release/faq/#valgrind
[145]PETSC ERROR: or try http://valgrind.org on GNU/linux and Apple MacOS to find memory corruption errors
[145]PETSC ERROR: configure using --with-debugging=yes, recompile, link, and run 
[145]PETSC ERROR: to get more information on the crash.
application called MPI_Abort(MPI_COMM_WORLD, 59) - process 145
[146]PETSC ERROR: ------------------------------------------------------------------------
[146]PETSC ERROR: Caught signal number 15 Terminate: Some process (or the batch system) has told this process to end
[146]PETSC ERROR: Try option -start_in_debugger or -on_error_attach_debugger
[146]PETSC ERROR: or see https://petsc.org/release/faq/#valgrind
[146]PETSC ERROR: or try http://valgrind.org on GNU/linux and Apple MacOS to find memory corruption errors
[146]PETSC ERROR: configure using --with-debugging=yes, recompile, link, and run 
[146]PETSC ERROR: to get more information on the crash.
application called MPI_Abort(MPI_COMM_WORLD, 59) - process 146
[147]PETSC ERROR: ------------------------------------------------------------------------
[147]PETSC ERROR: Caught signal number 15 Terminate: Some process (or the batch system) has told this process to end
[147]PETSC ERROR: Try option -start_in_debugger or -on_error_attach_debugger
[147]PETSC ERROR: or see https://petsc.org/release/faq/#valgrind
[147]PETSC ERROR: or try http://valgrind.org on GNU/linux and Apple MacOS to find memory corruption errors
[147]PETSC ERROR: configure using --with-debugging=yes, recompile, link, and run 
[147]PETSC ERROR: to get more information on the crash.
application called MPI_Abort(MPI_COMM_WORLD, 59) - process 147
[148]PETSC ERROR: ------------------------------------------------------------------------
[148]PETSC ERROR: Caught signal number 15 Terminate: Some process (or the batch system) has told this process to end
[148]PETSC ERROR: Try option -start_in_debugger or -on_error_attach_debugger
[148]PETSC ERROR: or see https://petsc.org/release/faq/#valgrind
[148]PETSC ERROR: or try http://valgrind.org on GNU/linux and Apple MacOS to find memory corruption errors
[148]PETSC ERROR: configure using --with-debugging=yes, recompile, link, and run 
[148]PETSC ERROR: to get more information on the crash.
application called MPI_Abort(MPI_COMM_WORLD, 59) - process 148
[149]PETSC ERROR: ------------------------------------------------------------------------
[149]PETSC ERROR: Caught signal number 15 Terminate: Some process (or the batch system) has told this process to end
[149]PETSC ERROR: Try option -start_in_debugger or -on_error_attach_debugger
[149]PETSC ERROR: or see https://petsc.org/release/faq/#valgrind
[149]PETSC ERROR: or try http://valgrind.org on GNU/linux and Apple MacOS to find memory corruption errors
[149]PETSC ERROR: configure using --with-debugging=yes, recompile, link, and run 
[149]PETSC ERROR: to get more information on the crash.
application called MPI_Abort(MPI_COMM_WORLD, 59) - process 149
[150]PETSC ERROR: ------------------------------------------------------------------------
[150]PETSC ERROR: Caught signal number 15 Terminate: Some process (or the batch system) has told this process to end
[150]PETSC ERROR: Try option -start_in_debugger or -on_error_attach_debugger
[150]PETSC ERROR: or see https://petsc.org/release/faq/#valgrind
[150]PETSC ERROR: or try http://valgrind.org on GNU/linux and Apple MacOS to find memory corruption errors
[150]PETSC ERROR: configure using --with-debugging=yes, recompile, link, and run 
[150]PETSC ERROR: to get more information on the crash.
application called MPI_Abort(MPI_COMM_WORLD, 59) - process 150
[153]PETSC ERROR: ------------------------------------------------------------------------
[153]PETSC ERROR: Caught signal number 15 Terminate: Some process (or the batch system) has told this process to end
[153]PETSC ERROR: Try option -start_in_debugger or -on_error_attach_debugger
[153]PETSC ERROR: or see https://petsc.org/release/faq/#valgrind
[153]PETSC ERROR: or try http://valgrind.org on GNU/linux and Apple MacOS to find memory corruption errors
[153]PETSC ERROR: configure using --with-debugging=yes, recompile, link, and run 
[153]PETSC ERROR: to get more information on the crash.
application called MPI_Abort(MPI_COMM_WORLD, 59) - process 153
[154]PETSC ERROR: ------------------------------------------------------------------------
[154]PETSC ERROR: Caught signal number 15 Terminate: Some process (or the batch system) has told this process to end
[154]PETSC ERROR: Try option -start_in_debugger or -on_error_attach_debugger
[154]PETSC ERROR: or see https://petsc.org/release/faq/#valgrind
[154]PETSC ERROR: or try http://valgrind.org on GNU/linux and Apple MacOS to find memory corruption errors
[154]PETSC ERROR: configure using --with-debugging=yes, recompile, link, and run 
[154]PETSC ERROR: to get more information on the crash.
application called MPI_Abort(MPI_COMM_WORLD, 59) - process 154
[158]PETSC ERROR: ------------------------------------------------------------------------
[158]PETSC ERROR: Caught signal number 15 Terminate: Some process (or the batch system) has told this process to end
[158]PETSC ERROR: Try option -start_in_debugger or -on_error_attach_debugger
[158]PETSC ERROR: or see https://petsc.org/release/faq/#valgrind
[158]PETSC ERROR: or try http://valgrind.org on GNU/linux and Apple MacOS to find memory corruption errors
[158]PETSC ERROR: configure using --with-debugging=yes, recompile, link, and run 
[158]PETSC ERROR: to get more information on the crash.
application called MPI_Abort(MPI_COMM_WORLD, 59) - process 158
[160]PETSC ERROR: ------------------------------------------------------------------------
[160]PETSC ERROR: Caught signal number 15 Terminate: Some process (or the batch system) has told this process to end
[160]PETSC ERROR: Try option -start_in_debugger or -on_error_attach_debugger
[160]PETSC ERROR: or see https://petsc.org/release/faq/#valgrind
[160]PETSC ERROR: or try http://valgrind.org on GNU/linux and Apple MacOS to find memory corruption errors
[160]PETSC ERROR: configure using --with-debugging=yes, recompile, link, and run 
[160]PETSC ERROR: to get more information on the crash.
application called MPI_Abort(MPI_COMM_WORLD, 59) - process 160
[161]PETSC ERROR: ------------------------------------------------------------------------
[161]PETSC ERROR: Caught signal number 15 Terminate: Some process (or the batch system) has told this process to end
[161]PETSC ERROR: Try option -start_in_debugger or -on_error_attach_debugger
[161]PETSC ERROR: or see https://petsc.org/release/faq/#valgrind
[161]PETSC ERROR: or try http://valgrind.org on GNU/linux and Apple MacOS to find memory corruption errors
[161]PETSC ERROR: configure using --with-debugging=yes, recompile, link, and run 
[161]PETSC ERROR: to get more information on the crash.
application called MPI_Abort(MPI_COMM_WORLD, 59) - process 161
[162]PETSC ERROR: ------------------------------------------------------------------------
[162]PETSC ERROR: Caught signal number 15 Terminate: Some process (or the batch system) has told this process to end
[162]PETSC ERROR: Try option -start_in_debugger or -on_error_attach_debugger
[162]PETSC ERROR: or see https://petsc.org/release/faq/#valgrind
[162]PETSC ERROR: or try http://valgrind.org on GNU/linux and Apple MacOS to find memory corruption errors
[162]PETSC ERROR: configure using --with-debugging=yes, recompile, link, and run 
[162]PETSC ERROR: to get more information on the crash.
application called MPI_Abort(MPI_COMM_WORLD, 59) - process 162
[163]PETSC ERROR: ------------------------------------------------------------------------
[163]PETSC ERROR: Caught signal number 15 Terminate: Some process (or the batch system) has told this process to end
[163]PETSC ERROR: Try option -start_in_debugger or -on_error_attach_debugger
[163]PETSC ERROR: or see https://petsc.org/release/faq/#valgrind
[163]PETSC ERROR: or try http://valgrind.org on GNU/linux and Apple MacOS to find memory corruption errors
[163]PETSC ERROR: configure using --with-debugging=yes, recompile, link, and run 
[163]PETSC ERROR: to get more information on the crash.
application called MPI_Abort(MPI_COMM_WORLD, 59) - process 163
[164]PETSC ERROR: ------------------------------------------------------------------------
[164]PETSC ERROR: Caught signal number 15 Terminate: Some process (or the batch system) has told this process to end
[164]PETSC ERROR: Try option -start_in_debugger or -on_error_attach_debugger
[164]PETSC ERROR: or see https://petsc.org/release/faq/#valgrind
[164]PETSC ERROR: or try http://valgrind.org on GNU/linux and Apple MacOS to find memory corruption errors
[164]PETSC ERROR: configure using --with-debugging=yes, recompile, link, and run 
[164]PETSC ERROR: to get more information on the crash.
application called MPI_Abort(MPI_COMM_WORLD, 59) - process 164
[167]PETSC ERROR: ------------------------------------------------------------------------
[167]PETSC ERROR: Caught signal number 15 Terminate: Some process (or the batch system) has told this process to end
[167]PETSC ERROR: Try option -start_in_debugger or -on_error_attach_debugger
[167]PETSC ERROR: or see https://petsc.org/release/faq/#valgrind
[167]PETSC ERROR: or try http://valgrind.org on GNU/linux and Apple MacOS to find memory corruption errors
[167]PETSC ERROR: configure using --with-debugging=yes, recompile, link, and run 
[167]PETSC ERROR: to get more information on the crash.
application called MPI_Abort(MPI_COMM_WORLD, 59) - process 167
[168]PETSC ERROR: ------------------------------------------------------------------------
[168]PETSC ERROR: Caught signal number 15 Terminate: Some process (or the batch system) has told this process to end
[168]PETSC ERROR: Try option -start_in_debugger or -on_error_attach_debugger
[168]PETSC ERROR: or see https://petsc.org/release/faq/#valgrind
[168]PETSC ERROR: or try http://valgrind.org on GNU/linux and Apple MacOS to find memory corruption errors
[168]PETSC ERROR: configure using --with-debugging=yes, recompile, link, and run 
[168]PETSC ERROR: to get more information on the crash.
application called MPI_Abort(MPI_COMM_WORLD, 59) - process 168
[170]PETSC ERROR: ------------------------------------------------------------------------
[170]PETSC ERROR: Caught signal number 15 Terminate: Some process (or the batch system) has told this process to end
[170]PETSC ERROR: Try option -start_in_debugger or -on_error_attach_debugger
[170]PETSC ERROR: or see https://petsc.org/release/faq/#valgrind
[170]PETSC ERROR: or try http://valgrind.org on GNU/linux and Apple MacOS to find memory corruption errors
[170]PETSC ERROR: configure using --with-debugging=yes, recompile, link, and run 
[170]PETSC ERROR: to get more information on the crash.
application called MPI_Abort(MPI_COMM_WORLD, 59) - process 170
[173]PETSC ERROR: ------------------------------------------------------------------------
[173]PETSC ERROR: Caught signal number 15 Terminate: Some process (or the batch system) has told this process to end
[173]PETSC ERROR: Try option -start_in_debugger or -on_error_attach_debugger
[173]PETSC ERROR: or see https://petsc.org/release/faq/#valgrind
[173]PETSC ERROR: or try http://valgrind.org on GNU/linux and Apple MacOS to find memory corruption errors
[173]PETSC ERROR: configure using --with-debugging=yes, recompile, link, and run 
[173]PETSC ERROR: to get more information on the crash.
application called MPI_Abort(MPI_COMM_WORLD, 59) - process 173
[174]PETSC ERROR: ------------------------------------------------------------------------
[174]PETSC ERROR: Caught signal number 15 Terminate: Some process (or the batch system) has told this process to end
[174]PETSC ERROR: Try option -start_in_debugger or -on_error_attach_debugger
[174]PETSC ERROR: or see https://petsc.org/release/faq/#valgrind
[174]PETSC ERROR: or try http://valgrind.org on GNU/linux and Apple MacOS to find memory corruption errors
[174]PETSC ERROR: configure using --with-debugging=yes, recompile, link, and run 
[174]PETSC ERROR: to get more information on the crash.
application called MPI_Abort(MPI_COMM_WORLD, 59) - process 174
[175]PETSC ERROR: ------------------------------------------------------------------------
[175]PETSC ERROR: Caught signal number 15 Terminate: Some process (or the batch system) has told this process to end
[175]PETSC ERROR: Try option -start_in_debugger or -on_error_attach_debugger
[175]PETSC ERROR: or see https://petsc.org/release/faq/#valgrind
[175]PETSC ERROR: or try http://valgrind.org on GNU/linux and Apple MacOS to find memory corruption errors
[175]PETSC ERROR: configure using --with-debugging=yes, recompile, link, and run 
[175]PETSC ERROR: to get more information on the crash.
application called MPI_Abort(MPI_COMM_WORLD, 59) - process 175
[176]PETSC ERROR: ------------------------------------------------------------------------
[176]PETSC ERROR: Caught signal number 15 Terminate: Some process (or the batch system) has told this process to end
[176]PETSC ERROR: Try option -start_in_debugger or -on_error_attach_debugger
[176]PETSC ERROR: or see https://petsc.org/release/faq/#valgrind
[176]PETSC ERROR: or try http://valgrind.org on GNU/linux and Apple MacOS to find memory corruption errors
[176]PETSC ERROR: configure using --with-debugging=yes, recompile, link, and run 
[176]PETSC ERROR: to get more information on the crash.
application called MPI_Abort(MPI_COMM_WORLD, 59) - process 176
[177]PETSC ERROR: ------------------------------------------------------------------------
[177]PETSC ERROR: Caught signal number 15 Terminate: Some process (or the batch system) has told this process to end
[177]PETSC ERROR: Try option -start_in_debugger or -on_error_attach_debugger
[177]PETSC ERROR: or see https://petsc.org/release/faq/#valgrind
[177]PETSC ERROR: or try http://valgrind.org on GNU/linux and Apple MacOS to find memory corruption errors
[177]PETSC ERROR: configure using --with-debugging=yes, recompile, link, and run 
[177]PETSC ERROR: to get more information on the crash.
application called MPI_Abort(MPI_COMM_WORLD, 59) - process 177
[179]PETSC ERROR: ------------------------------------------------------------------------
[179]PETSC ERROR: Caught signal number 15 Terminate: Some process (or the batch system) has told this process to end
[179]PETSC ERROR: Try option -start_in_debugger or -on_error_attach_debugger
[179]PETSC ERROR: or see https://petsc.org/release/faq/#valgrind
[179]PETSC ERROR: or try http://valgrind.org on GNU/linux and Apple MacOS to find memory corruption errors
[179]PETSC ERROR: configure using --with-debugging=yes, recompile, link, and run 
[179]PETSC ERROR: to get more information on the crash.
application called MPI_Abort(MPI_COMM_WORLD, 59) - process 179
[182]PETSC ERROR: ------------------------------------------------------------------------
[182]PETSC ERROR: Caught signal number 15 Terminate: Some process (or the batch system) has told this process to end
[182]PETSC ERROR: Try option -start_in_debugger or -on_error_attach_debugger
[182]PETSC ERROR: or see https://petsc.org/release/faq/#valgrind
[182]PETSC ERROR: or try http://valgrind.org on GNU/linux and Apple MacOS to find memory corruption errors
[182]PETSC ERROR: configure using --with-debugging=yes, recompile, link, and run 
[182]PETSC ERROR: to get more information on the crash.
application called MPI_Abort(MPI_COMM_WORLD, 59) - process 182
[184]PETSC ERROR: ------------------------------------------------------------------------
[184]PETSC ERROR: Caught signal number 15 Terminate: Some process (or the batch system) has told this process to end
[184]PETSC ERROR: Try option -start_in_debugger or -on_error_attach_debugger
[184]PETSC ERROR: or see https://petsc.org/release/faq/#valgrind
[184]PETSC ERROR: or try http://valgrind.org on GNU/linux and Apple MacOS to find memory corruption errors
[184]PETSC ERROR: configure using --with-debugging=yes, recompile, link, and run 
[184]PETSC ERROR: to get more information on the crash.
application called MPI_Abort(MPI_COMM_WORLD, 59) - process 184
[186]PETSC ERROR: ------------------------------------------------------------------------
[186]PETSC ERROR: Caught signal number 15 Terminate: Some process (or the batch system) has told this process to end
[186]PETSC ERROR: Try option -start_in_debugger or -on_error_attach_debugger
[186]PETSC ERROR: or see https://petsc.org/release/faq/#valgrind
[186]PETSC ERROR: or try http://valgrind.org on GNU/linux and Apple MacOS to find memory corruption errors
[186]PETSC ERROR: configure using --with-debugging=yes, recompile, link, and run 
[186]PETSC ERROR: to get more information on the crash.
application called MPI_Abort(MPI_COMM_WORLD, 59) - process 186
[187]PETSC ERROR: ------------------------------------------------------------------------
[187]PETSC ERROR: Caught signal number 15 Terminate: Some process (or the batch system) has told this process to end
[187]PETSC ERROR: Try option -start_in_debugger or -on_error_attach_debugger
[187]PETSC ERROR: or see https://petsc.org/release/faq/#valgrind
[187]PETSC ERROR: or try http://valgrind.org on GNU/linux and Apple MacOS to find memory corruption errors
[187]PETSC ERROR: configure using --with-debugging=yes, recompile, link, and run 
[187]PETSC ERROR: to get more information on the crash.
application called MPI_Abort(MPI_COMM_WORLD, 59) - process 187
[189]PETSC ERROR: ------------------------------------------------------------------------
[189]PETSC ERROR: Caught signal number 15 Terminate: Some process (or the batch system) has told this process to end
[189]PETSC ERROR: Try option -start_in_debugger or -on_error_attach_debugger
[189]PETSC ERROR: or see https://petsc.org/release/faq/#valgrind
[189]PETSC ERROR: or try http://valgrind.org on GNU/linux and Apple MacOS to find memory corruption errors
[189]PETSC ERROR: configure using --with-debugging=yes, recompile, link, and run 
[189]PETSC ERROR: to get more information on the crash.
application called MPI_Abort(MPI_COMM_WORLD, 59) - process 189
[191]PETSC ERROR: ------------------------------------------------------------------------
[191]PETSC ERROR: Caught signal number 15 Terminate: Some process (or the batch system) has told this process to end
[191]PETSC ERROR: Try option -start_in_debugger or -on_error_attach_debugger
[191]PETSC ERROR: or see https://petsc.org/release/faq/#valgrind
[191]PETSC ERROR: or try http://valgrind.org on GNU/linux and Apple MacOS to find memory corruption errors
[191]PETSC ERROR: configure using --with-debugging=yes, recompile, link, and run 
[191]PETSC ERROR: to get more information on the crash.
application called MPI_Abort(MPI_COMM_WORLD, 59) - process 191
[193]PETSC ERROR: ------------------------------------------------------------------------
[193]PETSC ERROR: Caught signal number 15 Terminate: Some process (or the batch system) has told this process to end
[193]PETSC ERROR: Try option -start_in_debugger or -on_error_attach_debugger
[193]PETSC ERROR: or see https://petsc.org/release/faq/#valgrind
[193]PETSC ERROR: or try http://valgrind.org on GNU/linux and Apple MacOS to find memory corruption errors
[193]PETSC ERROR: configure using --with-debugging=yes, recompile, link, and run 
[193]PETSC ERROR: to get more information on the crash.
application called MPI_Abort(MPI_COMM_WORLD, 59) - process 193
[194]PETSC ERROR: ------------------------------------------------------------------------
[194]PETSC ERROR: Caught signal number 15 Terminate: Some process (or the batch system) has told this process to end
[194]PETSC ERROR: Try option -start_in_debugger or -on_error_attach_debugger
[194]PETSC ERROR: or see https://petsc.org/release/faq/#valgrind
[194]PETSC ERROR: or try http://valgrind.org on GNU/linux and Apple MacOS to find memory corruption errors
[194]PETSC ERROR: configure using --with-debugging=yes, recompile, link, and run 
[194]PETSC ERROR: to get more information on the crash.
application called MPI_Abort(MPI_COMM_WORLD, 59) - process 194
[195]PETSC ERROR: ------------------------------------------------------------------------
[195]PETSC ERROR: Caught signal number 15 Terminate: Some process (or the batch system) has told this process to end
[195]PETSC ERROR: Try option -start_in_debugger or -on_error_attach_debugger
[195]PETSC ERROR: or see https://petsc.org/release/faq/#valgrind
[195]PETSC ERROR: or try http://valgrind.org on GNU/linux and Apple MacOS to find memory corruption errors
[195]PETSC ERROR: configure using --with-debugging=yes, recompile, link, and run 
[195]PETSC ERROR: to get more information on the crash.
application called MPI_Abort(MPI_COMM_WORLD, 59) - process 195
[196]PETSC ERROR: ------------------------------------------------------------------------
[196]PETSC ERROR: Caught signal number 15 Terminate: Some process (or the batch system) has told this process to end
[196]PETSC ERROR: Try option -start_in_debugger or -on_error_attach_debugger
[196]PETSC ERROR: or see https://petsc.org/release/faq/#valgrind
[196]PETSC ERROR: or try http://valgrind.org on GNU/linux and Apple MacOS to find memory corruption errors
[196]PETSC ERROR: configure using --with-debugging=yes, recompile, link, and run 
[196]PETSC ERROR: to get more information on the crash.
application called MPI_Abort(MPI_COMM_WORLD, 59) - process 196
[197]PETSC ERROR: ------------------------------------------------------------------------
[197]PETSC ERROR: Caught signal number 15 Terminate: Some process (or the batch system) has told this process to end
[197]PETSC ERROR: Try option -start_in_debugger or -on_error_attach_debugger
[197]PETSC ERROR: or see https://petsc.org/release/faq/#valgrind
[197]PETSC ERROR: or try http://valgrind.org on GNU/linux and Apple MacOS to find memory corruption errors
[197]PETSC ERROR: configure using --with-debugging=yes, recompile, link, and run 
[197]PETSC ERROR: to get more information on the crash.
application called MPI_Abort(MPI_COMM_WORLD, 59) - process 197
[201]PETSC ERROR: ------------------------------------------------------------------------
[201]PETSC ERROR: Caught signal number 15 Terminate: Some process (or the batch system) has told this process to end
[201]PETSC ERROR: Try option -start_in_debugger or -on_error_attach_debugger
[201]PETSC ERROR: or see https://petsc.org/release/faq/#valgrind
[201]PETSC ERROR: or try http://valgrind.org on GNU/linux and Apple MacOS to find memory corruption errors
[201]PETSC ERROR: configure using --with-debugging=yes, recompile, link, and run 
[201]PETSC ERROR: to get more information on the crash.
application called MPI_Abort(MPI_COMM_WORLD, 59) - process 201
[199]PETSC ERROR: ------------------------------------------------------------------------
[199]PETSC ERROR: Caught signal number 15 Terminate: Some process (or the batch system) has told this process to end
[199]PETSC ERROR: Try option -start_in_debugger or -on_error_attach_debugger
[199]PETSC ERROR: or see https://petsc.org/release/faq/#valgrind
[199]PETSC ERROR: or try http://valgrind.org on GNU/linux and Apple MacOS to find memory corruption errors
[199]PETSC ERROR: configure using --with-debugging=yes, recompile, link, and run 
[199]PETSC ERROR: to get more information on the crash.
application called MPI_Abort(MPI_COMM_WORLD, 59) - process 199
[204]PETSC ERROR: ------------------------------------------------------------------------
[204]PETSC ERROR: Caught signal number 15 Terminate: Some process (or the batch system) has told this process to end
[204]PETSC ERROR: Try option -start_in_debugger or -on_error_attach_debugger
[204]PETSC ERROR: or see https://petsc.org/release/faq/#valgrind
[204]PETSC ERROR: or try http://valgrind.org on GNU/linux and Apple MacOS to find memory corruption errors
[204]PETSC ERROR: configure using --with-debugging=yes, recompile, link, and run 
[204]PETSC ERROR: to get more information on the crash.
application called MPI_Abort(MPI_COMM_WORLD, 59) - process 204
[205]PETSC ERROR: ------------------------------------------------------------------------
[205]PETSC ERROR: Caught signal number 15 Terminate: Some process (or the batch system) has told this process to end
[205]PETSC ERROR: Try option -start_in_debugger or -on_error_attach_debugger
[205]PETSC ERROR: or see https://petsc.org/release/faq/#valgrind
[205]PETSC ERROR: or try http://valgrind.org on GNU/linux and Apple MacOS to find memory corruption errors
[205]PETSC ERROR: configure using --with-debugging=yes, recompile, link, and run 
[205]PETSC ERROR: to get more information on the crash.
application called MPI_Abort(MPI_COMM_WORLD, 59) - process 205
[207]PETSC ERROR: ------------------------------------------------------------------------
[207]PETSC ERROR: Caught signal number 15 Terminate: Some process (or the batch system) has told this process to end
[207]PETSC ERROR: Try option -start_in_debugger or -on_error_attach_debugger
[207]PETSC ERROR: or see https://petsc.org/release/faq/#valgrind
[207]PETSC ERROR: or try http://valgrind.org on GNU/linux and Apple MacOS to find memory corruption errors
[207]PETSC ERROR: configure using --with-debugging=yes, recompile, link, and run 
[207]PETSC ERROR: to get more information on the crash.
application called MPI_Abort(MPI_COMM_WORLD, 59) - process 207
[208]PETSC ERROR: ------------------------------------------------------------------------
[208]PETSC ERROR: Caught signal number 15 Terminate: Some process (or the batch system) has told this process to end
[208]PETSC ERROR: Try option -start_in_debugger or -on_error_attach_debugger
[208]PETSC ERROR: or see https://petsc.org/release/faq/#valgrind
[208]PETSC ERROR: or try http://valgrind.org on GNU/linux and Apple MacOS to find memory corruption errors
[208]PETSC ERROR: configure using --with-debugging=yes, recompile, link, and run 
[208]PETSC ERROR: to get more information on the crash.
application called MPI_Abort(MPI_COMM_WORLD, 59) - process 208
[210]PETSC ERROR: ------------------------------------------------------------------------
[210]PETSC ERROR: Caught signal number 15 Terminate: Some process (or the batch system) has told this process to end
[210]PETSC ERROR: Try option -start_in_debugger or -on_error_attach_debugger
[210]PETSC ERROR: or see https://petsc.org/release/faq/#valgrind
[210]PETSC ERROR: or try http://valgrind.org on GNU/linux and Apple MacOS to find memory corruption errors
[210]PETSC ERROR: configure using --with-debugging=yes, recompile, link, and run 
[210]PETSC ERROR: to get more information on the crash.
application called MPI_Abort(MPI_COMM_WORLD, 59) - process 210
[211]PETSC ERROR: ------------------------------------------------------------------------
[211]PETSC ERROR: Caught signal number 15 Terminate: Some process (or the batch system) has told this process to end
[211]PETSC ERROR: Try option -start_in_debugger or -on_error_attach_debugger
[211]PETSC ERROR: or see https://petsc.org/release/faq/#valgrind
[211]PETSC ERROR: or try http://valgrind.org on GNU/linux and Apple MacOS to find memory corruption errors
[211]PETSC ERROR: configure using --with-debugging=yes, recompile, link, and run 
[211]PETSC ERROR: to get more information on the crash.
application called MPI_Abort(MPI_COMM_WORLD, 59) - process 211
[214]PETSC ERROR: ------------------------------------------------------------------------
[214]PETSC ERROR: Caught signal number 15 Terminate: Some process (or the batch system) has told this process to end
[214]PETSC ERROR: Try option -start_in_debugger or -on_error_attach_debugger
[214]PETSC ERROR: or see https://petsc.org/release/faq/#valgrind
[214]PETSC ERROR: or try http://valgrind.org on GNU/linux and Apple MacOS to find memory corruption errors
[214]PETSC ERROR: configure using --with-debugging=yes, recompile, link, and run 
[214]PETSC ERROR: to get more information on the crash.
application called MPI_Abort(MPI_COMM_WORLD, 59) - process 214
[215]PETSC ERROR: ------------------------------------------------------------------------
[215]PETSC ERROR: Caught signal number 15 Terminate: Some process (or the batch system) has told this process to end
[215]PETSC ERROR: Try option -start_in_debugger or -on_error_attach_debugger
[215]PETSC ERROR: or see https://petsc.org/release/faq/#valgrind
[215]PETSC ERROR: or try http://valgrind.org on GNU/linux and Apple MacOS to find memory corruption errors
[215]PETSC ERROR: configure using --with-debugging=yes, recompile, link, and run 
[215]PETSC ERROR: to get more information on the crash.
application called MPI_Abort(MPI_COMM_WORLD, 59) - process 215
[216]PETSC ERROR: ------------------------------------------------------------------------
[216]PETSC ERROR: Caught signal number 15 Terminate: Some process (or the batch system) has told this process to end
[216]PETSC ERROR: Try option -start_in_debugger or -on_error_attach_debugger
[216]PETSC ERROR: or see https://petsc.org/release/faq/#valgrind
[216]PETSC ERROR: or try http://valgrind.org on GNU/linux and Apple MacOS to find memory corruption errors
[216]PETSC ERROR: configure using --with-debugging=yes, recompile, link, and run 
[216]PETSC ERROR: to get more information on the crash.
application called MPI_Abort(MPI_COMM_WORLD, 59) - process 216
[217]PETSC ERROR: ------------------------------------------------------------------------
[217]PETSC ERROR: Caught signal number 15 Terminate: Some process (or the batch system) has told this process to end
[217]PETSC ERROR: Try option -start_in_debugger or -on_error_attach_debugger
[217]PETSC ERROR: or see https://petsc.org/release/faq/#valgrind
[217]PETSC ERROR: or try http://valgrind.org on GNU/linux and Apple MacOS to find memory corruption errors
[217]PETSC ERROR: configure using --with-debugging=yes, recompile, link, and run 
[217]PETSC ERROR: to get more information on the crash.
application called MPI_Abort(MPI_COMM_WORLD, 59) - process 217
[219]PETSC ERROR: ------------------------------------------------------------------------
[219]PETSC ERROR: Caught signal number 15 Terminate: Some process (or the batch system) has told this process to end
[219]PETSC ERROR: Try option -start_in_debugger or -on_error_attach_debugger
[219]PETSC ERROR: or see https://petsc.org/release/faq/#valgrind
[219]PETSC ERROR: or try http://valgrind.org on GNU/linux and Apple MacOS to find memory corruption errors
[219]PETSC ERROR: configure using --with-debugging=yes, recompile, link, and run 
[219]PETSC ERROR: to get more information on the crash.
application called MPI_Abort(MPI_COMM_WORLD, 59) - process 219
[220]PETSC ERROR: ------------------------------------------------------------------------
[220]PETSC ERROR: Caught signal number 15 Terminate: Some process (or the batch system) has told this process to end
[220]PETSC ERROR: Try option -start_in_debugger or -on_error_attach_debugger
[220]PETSC ERROR: or see https://petsc.org/release/faq/#valgrind
[220]PETSC ERROR: or try http://valgrind.org on GNU/linux and Apple MacOS to find memory corruption errors
[220]PETSC ERROR: configure using --with-debugging=yes, recompile, link, and run 
[220]PETSC ERROR: to get more information on the crash.
application called MPI_Abort(MPI_COMM_WORLD, 59) - process 220
[223]PETSC ERROR: ------------------------------------------------------------------------
[223]PETSC ERROR: Caught signal number 15 Terminate: Some process (or the batch system) has told this process to end
[223]PETSC ERROR: Try option -start_in_debugger or -on_error_attach_debugger
[223]PETSC ERROR: or see https://petsc.org/release/faq/#valgrind
[223]PETSC ERROR: or try http://valgrind.org on GNU/linux and Apple MacOS to find memory corruption errors
[223]PETSC ERROR: configure using --with-debugging=yes, recompile, link, and run 
[223]PETSC ERROR: to get more information on the crash.
application called MPI_Abort(MPI_COMM_WORLD, 59) - process 223
[224]PETSC ERROR: ------------------------------------------------------------------------
[224]PETSC ERROR: Caught signal number 15 Terminate: Some process (or the batch system) has told this process to end
[224]PETSC ERROR: Try option -start_in_debugger or -on_error_attach_debugger
[224]PETSC ERROR: or see https://petsc.org/release/faq/#valgrind
[224]PETSC ERROR: or try http://valgrind.org on GNU/linux and Apple MacOS to find memory corruption errors
[224]PETSC ERROR: configure using --with-debugging=yes, recompile, link, and run 
[224]PETSC ERROR: to get more information on the crash.
application called MPI_Abort(MPI_COMM_WORLD, 59) - process 224
[226]PETSC ERROR: ------------------------------------------------------------------------
[226]PETSC ERROR: Caught signal number 15 Terminate: Some process (or the batch system) has told this process to end
[226]PETSC ERROR: Try option -start_in_debugger or -on_error_attach_debugger
[226]PETSC ERROR: or see https://petsc.org/release/faq/#valgrind
[226]PETSC ERROR: or try http://valgrind.org on GNU/linux and Apple MacOS to find memory corruption errors
[226]PETSC ERROR: configure using --with-debugging=yes, recompile, link, and run 
[226]PETSC ERROR: to get more information on the crash.
application called MPI_Abort(MPI_COMM_WORLD, 59) - process 226
[228]PETSC ERROR: ------------------------------------------------------------------------
[228]PETSC ERROR: Caught signal number 15 Terminate: Some process (or the batch system) has told this process to end
[228]PETSC ERROR: Try option -start_in_debugger or -on_error_attach_debugger
[228]PETSC ERROR: or see https://petsc.org/release/faq/#valgrind
[228]PETSC ERROR: or try http://valgrind.org on GNU/linux and Apple MacOS to find memory corruption errors
[228]PETSC ERROR: configure using --with-debugging=yes, recompile, link, and run 
[228]PETSC ERROR: to get more information on the crash.
application called MPI_Abort(MPI_COMM_WORLD, 59) - process 228
[229]PETSC ERROR: ------------------------------------------------------------------------
[229]PETSC ERROR: Caught signal number 15 Terminate: Some process (or the batch system) has told this process to end
[229]PETSC ERROR: Try option -start_in_debugger or -on_error_attach_debugger
[229]PETSC ERROR: or see https://petsc.org/release/faq/#valgrind
[229]PETSC ERROR: or try http://valgrind.org on GNU/linux and Apple MacOS to find memory corruption errors
[229]PETSC ERROR: configure using --with-debugging=yes, recompile, link, and run 
[229]PETSC ERROR: to get more information on the crash.
application called MPI_Abort(MPI_COMM_WORLD, 59) - process 229
[231]PETSC ERROR: ------------------------------------------------------------------------
[231]PETSC ERROR: Caught signal number 15 Terminate: Some process (or the batch system) has told this process to end
[231]PETSC ERROR: Try option -start_in_debugger or -on_error_attach_debugger
[231]PETSC ERROR: or see https://petsc.org/release/faq/#valgrind
[231]PETSC ERROR: or try http://valgrind.org on GNU/linux and Apple MacOS to find memory corruption errors
[231]PETSC ERROR: configure using --with-debugging=yes, recompile, link, and run 
[231]PETSC ERROR: to get more information on the crash.
application called MPI_Abort(MPI_COMM_WORLD, 59) - process 231
[232]PETSC ERROR: ------------------------------------------------------------------------
[232]PETSC ERROR: Caught signal number 15 Terminate: Some process (or the batch system) has told this process to end
[232]PETSC ERROR: Try option -start_in_debugger or -on_error_attach_debugger
[232]PETSC ERROR: or see https://petsc.org/release/faq/#valgrind
[232]PETSC ERROR: or try http://valgrind.org on GNU/linux and Apple MacOS to find memory corruption errors
[232]PETSC ERROR: configure using --with-debugging=yes, recompile, link, and run 
[232]PETSC ERROR: to get more information on the crash.
application called MPI_Abort(MPI_COMM_WORLD, 59) - process 232
[234]PETSC ERROR: ------------------------------------------------------------------------
[234]PETSC ERROR: Caught signal number 15 Terminate: Some process (or the batch system) has told this process to end
[234]PETSC ERROR: Try option -start_in_debugger or -on_error_attach_debugger
[234]PETSC ERROR: or see https://petsc.org/release/faq/#valgrind
[234]PETSC ERROR: or try http://valgrind.org on GNU/linux and Apple MacOS to find memory corruption errors
[234]PETSC ERROR: configure using --with-debugging=yes, recompile, link, and run 
[234]PETSC ERROR: to get more information on the crash.
application called MPI_Abort(MPI_COMM_WORLD, 59) - process 234
[235]PETSC ERROR: ------------------------------------------------------------------------
[235]PETSC ERROR: Caught signal number 15 Terminate: Some process (or the batch system) has told this process to end
[235]PETSC ERROR: Try option -start_in_debugger or -on_error_attach_debugger
[235]PETSC ERROR: or see https://petsc.org/release/faq/#valgrind
[235]PETSC ERROR: or try http://valgrind.org on GNU/linux and Apple MacOS to find memory corruption errors
[235]PETSC ERROR: configure using --with-debugging=yes, recompile, link, and run 
[235]PETSC ERROR: to get more information on the crash.
application called MPI_Abort(MPI_COMM_WORLD, 59) - process 235
[236]PETSC ERROR: ------------------------------------------------------------------------
[236]PETSC ERROR: Caught signal number 15 Terminate: Some process (or the batch system) has told this process to end
[236]PETSC ERROR: Try option -start_in_debugger or -on_error_attach_debugger
[236]PETSC ERROR: or see https://petsc.org/release/faq/#valgrind
[236]PETSC ERROR: or try http://valgrind.org on GNU/linux and Apple MacOS to find memory corruption errors
[236]PETSC ERROR: configure using --with-debugging=yes, recompile, link, and run 
[236]PETSC ERROR: to get more information on the crash.
application called MPI_Abort(MPI_COMM_WORLD, 59) - process 236
[238]PETSC ERROR: ------------------------------------------------------------------------
[238]PETSC ERROR: Caught signal number 15 Terminate: Some process (or the batch system) has told this process to end
[238]PETSC ERROR: Try option -start_in_debugger or -on_error_attach_debugger
[238]PETSC ERROR: or see https://petsc.org/release/faq/#valgrind
[238]PETSC ERROR: or try http://valgrind.org on GNU/linux and Apple MacOS to find memory corruption errors
[238]PETSC ERROR: configure using --with-debugging=yes, recompile, link, and run 
[238]PETSC ERROR: to get more information on the crash.
application called MPI_Abort(MPI_COMM_WORLD, 59) - process 238
[239]PETSC ERROR: ------------------------------------------------------------------------
[239]PETSC ERROR: Caught signal number 15 Terminate: Some process (or the batch system) has told this process to end
[239]PETSC ERROR: Try option -start_in_debugger or -on_error_attach_debugger
[239]PETSC ERROR: or see https://petsc.org/release/faq/#valgrind
[239]PETSC ERROR: or try http://valgrind.org on GNU/linux and Apple MacOS to find memory corruption errors
[239]PETSC ERROR: configure using --with-debugging=yes, recompile, link, and run 
[239]PETSC ERROR: to get more information on the crash.
application called MPI_Abort(MPI_COMM_WORLD, 59) - process 239
[240]PETSC ERROR: ------------------------------------------------------------------------
[240]PETSC ERROR: Caught signal number 15 Terminate: Some process (or the batch system) has told this process to end
[240]PETSC ERROR: Try option -start_in_debugger or -on_error_attach_debugger
[240]PETSC ERROR: or see https://petsc.org/release/faq/#valgrind
[240]PETSC ERROR: or try http://valgrind.org on GNU/linux and Apple MacOS to find memory corruption errors
[240]PETSC ERROR: configure using --with-debugging=yes, recompile, link, and run 
[240]PETSC ERROR: to get more information on the crash.
application called MPI_Abort(MPI_COMM_WORLD, 59) - process 240
[241]PETSC ERROR: ------------------------------------------------------------------------
[241]PETSC ERROR: Caught signal number 15 Terminate: Some process (or the batch system) has told this process to end
[241]PETSC ERROR: Try option -start_in_debugger or -on_error_attach_debugger
[241]PETSC ERROR: or see https://petsc.org/release/faq/#valgrind
[241]PETSC ERROR: or try http://valgrind.org on GNU/linux and Apple MacOS to find memory corruption errors
[241]PETSC ERROR: configure using --with-debugging=yes, recompile, link, and run 
[241]PETSC ERROR: to get more information on the crash.
application called MPI_Abort(MPI_COMM_WORLD, 59) - process 241
[242]PETSC ERROR: ------------------------------------------------------------------------
[242]PETSC ERROR: Caught signal number 15 Terminate: Some process (or the batch system) has told this process to end
[242]PETSC ERROR: Try option -start_in_debugger or -on_error_attach_debugger
[242]PETSC ERROR: or see https://petsc.org/release/faq/#valgrind
[242]PETSC ERROR: or try http://valgrind.org on GNU/linux and Apple MacOS to find memory corruption errors
[242]PETSC ERROR: configure using --with-debugging=yes, recompile, link, and run 
[242]PETSC ERROR: to get more information on the crash.
application called MPI_Abort(MPI_COMM_WORLD, 59) - process 242
